Workbook

Sheet PEMBELIAN KREDIT
A5: LAPORAN PEMBELIAN BAHAN ( KREDIT )
H7: CABANG | I7: : | J7: =LPKK!Q4 -> SC MARABAHAN
H8: PERIODE | I8: : | J8: =LPKK!Q5 -> 1-7 JULI 2026
A10: TANGGAL | B10: NAMA SUPLIER | C10: NAMA BAHAN | D10: NOMOR | E10: JUMLAH | F10: HARGA | G10: TOTAL | H10: TOTAL PPN | I10: UNIT PPN | J10: TANGGAL | K10: TANGGAL
D11: FAKTUR | E11: ( UNIT ) | F11: ( UNIT ) | H11: 0.11 | J11: JTH TEMPO | K11: DIBAYAR
A13: 46209 | B13: BERKAH MARKET | C13: BERAS | E13: 175 | F13: 16600 | G13: =F13*E13 -> 2905000
C14: TEPUNG | E14: 75 | F14: 10080 | G14: =F14*E14 -> 756000
A15: 46205 | B15: PT AMANAH BAGUS INDONRSIA | C15: BARGUD | E15: 1 | F15: 7994348 | G15: =F15*E15 -> 7994348
G16: =F16*E16 -> 0
G17: =F17*E17 -> 0
G18: =F18*E18 -> 0
G19: =F19*E19 -> 0
G20: =F20*E20 -> 0
G21: =F21*E21 -> 0
G22: =F22*E22 -> 0
G23: =F23*E23 -> 0
G24: =F24*E24 -> 0
G25: =F25*E25 -> 0
G26: =F26*E26 -> 0
A27: SUB TOTAL KREDIT BARGUD | G27: =SUM(G13:G26) -> 11655348
C28: MARINADE | D28: KARKAS | F28: 2273 | G28: =F28*E28 -> 0
D29: WHOLE | F29: 1855 | G29: =F29*E29 -> 0
A30: SUB TOTAL MARINADE | G30: =SUM(G28:G29) -> 0
A31: TANGGAL | B31: NAMA SUPLIER | C31: NOMER FAKTUR | D31: NAMA UNIT | E31: BERAT PCS | F31: BERAT EKOR | G31: HARGA TOTAL | H31: HARGA PER UNIT | I31: UNIT | J31: HARGA PER PCS
A32: 46205 | B32: CHICKEN GO | C32: PJL74773 | D32: MENTOK | E32: 130 | F32: 1200 | G32: 4111875 | H32: =E32/F32*G32 -> 445453.12 | I32: 85 | J32: =H32/I32 -> 5240.625
A33: 46209 | B33: CHICKEN GO | C33: PJL75242 | D33: DADA | E33: 310 | F33: 1200 | G33: 4111875 | H33: =E33/F33*G33 -> 1062234.4 | I33: 170 | J33: =H33/I33 -> 6248.4375
D34: PAHA ATAS | E34: 320 | F34: 1200 | G34: 4111875 | H34: =E34/F34*G34 -> 1096500 | I34: 170 | J34: =H34/I34 -> 6450
D35: PAHA BAWAH | E35: 230 | F35: 1200 | G35: 4111875 | H35: =E35/F35*G35 -> 788109.38 | I35: 170 | J35: =H35/I35 -> 4635.9375
D36: SAYAP | E36: 210 | F36: 1200 | G36: 4118875 | H36: =E36/F36*G36 -> 720803.12 | I36: 170 | J36: =H36/I36 -> 4240.0184
D37: SAYAP FULL | E37: 1200 | F37: 1200 | G37: 204085 | H37: =E37/F37*G37 -> 204085 | I37: 70 | J37: =H37/I37 -> 2915.5
D38: KULIT | E38: 1200 | F38: 1200 | G38: 369250 | H38: =E38/F38*G38 -> 369250 | I38: 10.55 | J38: =H38/I38 -> 35000
D39: P.BAWAH FULL | E39: 1200 | F39: 1200 | G39: 292600 | H39: =E39/F39*G39 -> 292600 | I39: 70 | J39: =H39/I39 -> 4180
D40: CUT 10 | E40: 1000 | F40: 1000 | G40: 204375 | H40: =E40/F40*G40 -> 204375 | I40: 50 | J40: =H40/I40 -> 4087.5
D41: WHOLE | E41: 1200 | F41: 1200 | G41: 1925600 | H41: =E41/F41*G41 -> 1925600 | I41: 80 | J41: =H41/I41 -> 24070
A42: SUB TOTAL KREDIT SUPLAYER | G42: =G36+G41-H42 -> -1064535 | H42: =SUM(H32:H41) -> 7109010
A43: SUB TOTAL KREDIT BARGUD & AYAM | G43: =SUM(H42+G30+G27) -> 18764358
J44: Paraf Supervisor

Sheet TO-TI
A2: TO / TI PERKEDEL | F2: TO / TI CATTERING STAFF | K2: TO / TI FREE | P2: TO / TI CHICKEN PATTY
C3: CABANG : | D3: =LPKK!Q4 -> SC MARABAHAN | H3: CABANG : | I3: =D3 -> SC MARABAHAN | M3: CABANG : | N3: =I3 -> SC MARABAHAN | R3: CABANG : | S3: =D3 -> SC MARABAHAN
C4: PERIODE / TGL : | D4: =LPKK!Q5 -> 1-7 JULI 2026 | H4: PERIODE / TGL : | I4: =D4 -> 1-7 JULI 2026 | M4: PERIODE / TGL : | N4: =I4 -> 1-7 JULI 2026 | R4: PERIODE / TGL : | S4: =D4 -> 1-7 JULI 2026
K5: FREE + VOUCER
A6: NAMA BAHAN | B6: QTY | C6: HARGA BELI | D6: TOTAL | F6: NAMA PRODUCT | G6: QTY | H6: HARGA JUAL | I6: TOTAL | K6: NAMA PRODUCT | L6: QTY | M6: HARGA JUAL | N6: TOTAL | P6: NAMA BAHAN | Q6: QTY | R6: HARGA BELI | S6: TOTAL
A7: KENTANG MANUAL | B7: =H34 -> 5000 | C7: =WEEKLY!E275 -> 25000 | D7: =B7/1000*C7 -> 125000 | F7: DADA | G7: 14 | H7: ='LAP. PENJUALAN REGULER'!S8 -> 15000 | I7: =H7*G7*G20 -> 120500.97 | K7: DADA | M7: =H7 -> 15000 | N7: =L7*M7*L21 -> 0 | P7: DAGING / MENTOK | Q7: 15 | R7: =WEEKLY!E11 -> 5240.625 | S7: =R7*Q7 -> 78609.375
A8: DAGING AYAM/MENTOK | C8: =WEEKLY!E11 -> 5240.625 | D8: =B8*C8 -> 0 | F8: P.ATAS | H8: ='LAP. PENJUALAN REGULER'!S9 -> 15000 | I8: =H8*G8*G20 -> 0 | K8: P.ATAS | M8: =H8 -> 15000 | N8: =L8*M8*L21 -> 0 | P8: PAHA BAWAH | R8: =WEEKLY!E14 -> 4635.9375 | S8: =R8*Q8 -> 0
A9: BATANG SLEDRI | B9: =H36 -> 100 | C9: =WEEKLY!E278 -> 10000 | D9: =B9/1000*C9 -> 1000 | F9: P.BAWAH | H9: ='LAP. PENJUALAN REGULER'!S10 -> 13500 | I9: =H9*G9*G20 -> 0 | K9: P.BAWAH | M9: =H9 -> 13500 | N9: =L9*M9*L21 -> 0 | P9: DAGING GILING | S9: =R9*Q9 -> 0
A10: KUNING TELUR | B10: =H37 -> 4 | C10: =WEEKLY!E282 -> 2322 | D10: =B10/16*C10 -> 580.5 | F10: SAYAP | H10: ='LAP. PENJUALAN REGULER'!S11 -> 12500 | I10: =H10*G10*G20 -> 0 | K10: SAYAP | M10: =H10 -> 12500 | N10: =L10*M10*L21 -> 0 | P10: ROTI TAWAR | Q10: =R37 -> 8 | R10: =WEEKLY!E48 -> 900 | S10: =R10/12*Q10 -> 600
A11: BAWANG MERAH | B11: =H38 -> 40 | C11: =WEEKLY!E280 -> 50000 | D11: =B11/1000*C11 -> 2000 | F11: NASI | G11: 14 | H11: ='LAP. PENJUALAN REGULER'!S16 -> 5000 | I11: =H11*G11*G20 -> 40166.99 | K11: NASI | M11: =H11 -> 5000 | N11: =L11*M11*L21 -> 0 | P11: SUSU ULTRA | Q11: =R38 -> 25 | R11: =WEEKLY!E51 -> 6000 | S11: =Q11/150*R11 -> 1000
A12: BAWANG PUTIH | B12: =H39 -> 10 | C12: =WEEKLY!E279 -> 40000 | D12: =B12/1000*C12 -> 400 | I12: =H12*G12*G20 -> 0 | M12: =H12 -> 0 | N12: =L12*M12*L21 -> 0 | P12: BAWANG BOMBAY | Q12: =R39 -> 50 | R12: =WEEKLY!E44 -> 40000 | S12: =Q12/1000*R12 -> 2000
A13: PREMIK PERKEDEL | I13: =H13*G13*G20 -> 0 | M13: =H13 -> 0 | N13: =M13*L13*L21 -> 0 | P13: TELUR | Q13: =R40 -> 4 | R13: =WEEKLY!E282 -> 2322 | S13: =Q13/16*R13 -> 580.5
A14: VETSIN | B14: =H41 -> 20 | C14: =WEEKLY!E274 -> 14000 | D14: =B14/250*C14 -> 1120 | I14: =H14*G14*G20 -> 0 | M14: =H14 -> 0 | N14: =M14*L14*L21 -> 0 | P14: MARGARIN | Q14: =R41 -> 10 | R14: =WEEKLY!E46 -> 7000 | S14: =Q14/200*R14 -> 350
A15: LADA | B15: =H42 -> 6 | C15: =WEEKLY!E277 -> 1500 | D15: =B15*C15 -> 9000 | I15: =H15*G15*G20 -> 0 | M15: =H15 -> 0 | N15: =M15*L15*L21 -> 0 | P15: VETSIN | Q15: =R42 -> 30 | R15: =WEEKLY!E274 -> 14000 | S15: =Q15/250*R15 -> 1680
A16: GARAM | B16: =H43 -> 10 | C16: =WEEKLY!E276 -> 8000 | D16: =C16/250*B16 -> 320 | I16: =H16*G16*G20 -> 0 | M16: =H16 -> 0 | N16: =M16*L16*L21 -> 0 | P16: LADA | Q16: =R43 -> 15 | R16: =WEEKLY!E277 -> 1500 | S16: =Q16/250*R16 -> 90
I17: =H17*G17*G20 -> 0 | M17: =H17 -> 0 | N17: =M17*L17*L21 -> 0 | P17: GARAM | Q17: =R44 -> 18 | R17: =WEEKLY!E276 -> 8000 | S17: =R17/250*Q17 -> 576
C18: SUB TOTAL | D18: =SUM(D7:D17) -> 139420.5 | I18: =H18*G18*G20 -> 0 | M18: =H18 -> 0 | N18: =M18*L18*L21 -> 0
I19: =H19*G19*G20 -> 0 | M19: =H19 -> 0 | N19: =M19*L19*L21 -> 0 | R19: SUB TOTAL | S19: =S7+S8+S10+S11+S12+S14+S15+S16+S17+S18+S9+S13 -> 85485.875
A20: Perkedel Jadi | B20: 72 | C20: HPP | D20: =D18/B20 -> 1936.3958 | F20: FOOD COST | G20: =H29 -> 0.57381414 | I20: =SUM(I7:I19) -> 160667.96
K21: FOOD COST | L21: =H29 -> 0.57381414 | M21: TOTAL | N21: =SUM(N7:N20) -> 0 | P21: Chicken Patty Jadi | Q21: 36 | S21: =S19/Q21 -> 2374.6076 | Y21: =SUM(V7:V20) -> 0
D22: PARAF | I22: PARAF | N22: PARAF | S22: PARAF
A29: BUAT BERAPA RESEP | B29: 2 | F29: FOOD COST PERIODE KEMARIN | H29: 0.57381414 | P29: BUAT BERAPA RESEP | Q29: 1
A32: TOLONG DIBACA SEBELUM MENGISI TO/TI | F32: RUMUS PERKEDEL | P32: RUMUS C. PATTY
A34: CATATAN : | F34: KENTANG MANUAL | G34: 2500 | H34: =G34*B29 -> 5000 | P34: DAGING / MENTOK
A35: 1. TO/TI PERKEDEL TINGGAL MENGISI MANUAL KOLOM | F35: DAGING AYAM/MENTOK | H35: =G35*B29 -> 0 | P35: PAHA BAWAH
A36: BUAT BERPA RESEP DAN PERKEDEL JADI . | F36: BATANG SLEDRI | G36: 50 | H36: =G36*B29 -> 100 | P36: DAGING GILING
A37: 2. TO/TI PERKEDEL KOLOM AYAM DI ISI MANUAL | F37: KUNING TELUR | G37: 2 | H37: =G37*B29 -> 4 | P37: ROTI TAWAR | Q37: 8 | R37: =Q37*Q29 -> 8
A38: 3. TO/TI FREE DIISI MANUAL | F38: BAWANG MERAH | G38: 20 | H38: =G38*B29 -> 40 | P38: SUSU ULTRA | Q38: 25 | R38: =Q38*Q29 -> 25
A39: 4. FOOD COST PERIODE KEMARIN DIISI DAN DISESUAIKAN | F39: BAWANG PUTIH | G39: 5 | H39: =G39*B29 -> 10 | P39: BAWANG BOMBAY | Q39: 50 | R39: =Q39*Q29 -> 50
A40: 5. TO/TI CATTERING STAFF DIISI MANUAL | F40: PREMIK PERKEDEL | H40: =G40*B29 -> 0 | P40: TELUR | Q40: 4 | R40: =Q40*Q29 -> 4
A41: 6. TO/TI CHICKEN PATTY DIISI MANUAL PAHA BAWAH ATAU | F41: VETSIN | G41: 10 | H41: =G41*B29 -> 20 | P41: MARGARIN | Q41: 10 | R41: =Q41*Q29 -> 10
A42: MENTOK YG DIGUNAKAN DAN BERAPA RESEP | F42: LADA | G42: 3 | H42: =G42*B29 -> 6 | P42: VETSIN | Q42: 30 | R42: =Q42*Q29 -> 30
A43: 7. TO/TI JUAL BARANG GUDANG DAN TO/TI FREE DIMASUKAN | F43: GARAM | G43: 5 | H43: =G43*B29 -> 10 | P43: LADA | Q43: 15 | R43: =Q43*Q29 -> 15
A44: MANUAL DI VENDOR | H44: =G44*B29 -> 0 | P44: GARAM | Q44: 18 | R44: =Q44*Q29 -> 18
A45: 8. KALO TIDAK BIKIN TO/TI PERKEDEL DAN CHCIKEN PATTY
A46: MAKA KOLOM BUAT BERAPA RESEP DI HAPUS SAJA
A59: 0

Sheet LPKK
A2: LAPORAN PENGELUARAN KAS KECIL
P4: CABANG : | Q4: SC MARABAHAN
P5: PERIODE : | Q5: 1-7 JULI 2026
A8: TGL | B8: NO | C8: BAHAN | D8: BAHAN | E8: BAHAN | F8: BAHAN | G8: BAHAN | H8: BAHAN | I8: MINYAK | J8: GROCERIES / | K8: BAHAN | L8: BAHAN | M8: TRANSPORT | N8: FOTO COPY / | O8: NO ACC | P8: LAIN - LAIN | S8: SALDO
B9: NOTA | C9: AYAM | D9: PELENGKAP | E9: ROTI | F9: ES | G9: MINUMAN | H9: PEMBUNGKUS | I9: GORENG | J9: BUMBU | K9: PERKEDEL | L9: PEMBERSIH | N9: ATK | P9: ( Rp ) | Q9: KETERANGAN | R9: JUMLAH
A10: 46204 | B10: 1 | D10: 84000 | Q10: FRENCH FRIES | R10: =SUM(C10:P10) -> 84000
B11: 2 | F11: 70000 | Q11: ES KRISTAL | R11: =SUM(C11:P11) -> 70000
B12: 3 | J12: 79500 | Q12: MIE TELUR, SAMSET | R12: =SUM(C12:P12) -> 79500
B13: 4 | J13: 4000 | Q13: TELUR | R13: =SUM(C13:P13) -> 4000
B14: 5 | E14: 4000 | J14: 12000 | K14: 10000 | Q14: SAYURAN | R14: =SUM(C14:P14) -> 26000
B15: 6 | P15: 260000 | Q15: GAS ELPIJI | R15: =SUM(C15:P15) -> 260000
B16: 7 | E16: 9000 | Q16: SELADA | R16: =SUM(C16:P16) -> 9000
B17: 8 | N17: 7000 | Q17: PRINT | R17: =SUM(C17:P17) -> 7000
B18: 9 | P18: 260000 | Q18: GAS ELPIJI | R18: =SUM(C18:P18) -> 260000
B19: 10 | E19: 10000 | F19: 100000 | H19: 20000 | J19: 31000 | Q19: GULA DLL | R19: =SUM(C19:P19) -> 161000
B20: 11 | P20: 203000 | Q20: TOKEN LISTRIK | R20: =SUM(C20:P20) -> 203000
B21: 12 | P21: 830500 | Q21: QRIS BRI | R21: =SUM(C21:P21) -> 830500
B22: 11 | R22: =SUM(C22:P22) -> 0
B23: 12 | R23: =SUM(C23:P23) -> 0
B24: 13 | R24: =SUM(C24:P24) -> 0
B25: 14 | R25: =SUM(C25:P25) -> 0
B26: 15 | R26: =SUM(C26:P26) -> 0
B27: 16 | R27: =SUM(C27:P27) -> 0
B28: 17 | R28: =SUM(C28:P28) -> 0
B29: 18 | R29: =SUM(C29:P29) -> 0
B30: 19 | R30: =SUM(C30:P30) -> 0
B31: 20 | R31: =SUM(C31:P31) -> 0
B32: 21 | R32: =SUM(C32:P32) -> 0
B33: 22 | R33: =SUM(C33:P33) -> 0
... B36: 25 | R36: =SUM(C36:P36) -> 0
A37: SUB TOTAL | C37: =SUM(C10:C36) -> 0 | D37: =SUM(D10:D36) -> 84000 | E37: =SUM(E10:E36) -> 23000 | F37: =SUM(F10:F36) -> 170000 | G37: =SUM(G10:G36) -> 0 | H37: =SUM(H10:H36) -> 20000 | I37: =SUM(I10:I36) -> 0 | J37: =SUM(J10:J36) -> 126500 | ... P37: =SUM(P10:P36) -> 1553500 | R37: =SUM(R10:R36) -> 1994000 | S37: =R37 -> 1994000
A38: 46205 | B38: 13 | E38: 15000 | J38: 16000 | K38: 10000 | Q38: SMSET,KEJU BATANG,LADA | R38: =SUM(C38:P38) -> 41000
B39: 14 | J39: 45000 | Q39: SAMSET | R39: =SUM(C39:P39) -> 45000
B40: 15 | D40: 64000 | Q40: RITI BURGER + SOSIS NASGOR | R40: =SUM(C40:P40) -> 64000
B41: 16 | E41: 20000 | Q41: ROTI TAWAR+SUSU | R41: =SUM(C41:P41) -> 20000
B42: 17 | F42: 100000 | Q42: GULA | R42: =SUM(C42:P42) -> 100000
B43: 18 | H43: 30000 | Q43: CUP SAMBAL | R43: =SUM(C43:P43) -> 30000
B44: 19 | P44: 117000 | Q44: APRON COOK+ CELEMEK KASIR | R44: =SUM(C44:P44) -> 117000
B45: 20 | J45: 21000 | K45: 5000 | Q45: SAYURAN | R45: =SUM(C45:P45) -> 26000
B46: 21 | M46: 500000 | Q46: ONGKIR BARGUD | R46: =SUM(C46:P46) -> 500000
...

Sheet VENDOR
M2: VENDOR REPORT | AI2: CABANG : | AJ2: =LPKK!Q4 -> SC MARABAHAN
AI3: PERIODE : | AJ3: =LPKK!Q5 -> 1-7 JULI 2026 | AQ3: PENCATATAN PEMBELIAN AYAM KREDIT
B5: TGL FAKTUR | C5: NO | E5: PEMAKAIAN | G5: PERSEDIAAN | I5: 46204 | K5: 46205 | M5: 46206 | O5: 46207 | Q5: 46208 | S5: 46209 | U5: 46210 | AC5: KHUSUS TO/TI ( - ) | AE5: KREDIT BARGUD | AG5: KREDIT BAHAN BAKU | AI5: TOTAL | AK5: PERSEDIAAN | AM5: PEMAKAIAN
D6: KETERANGAN BAHAN | E6: MINGGU LALU | G6: AWAL | AC6: C.PATTY/CATTERING STAFF( - ) | AI6: PEMBELIAN | AK6: AKHIR | AM6: MINGGU INI | AP6: TGL FAKTUR | AQ6: 44947
B7: HARI | E7: DLM SATUAN | G7: DLM SATUAN | I7: RABU | K7: KAMIS | M7: JUM'AT | O7: SABTU | Q7: MINGGU | S7: SENIN | U7: SELASA | AC7: PERKEDEL/BARGUD | AG7: AYAM DLL | AI7: DLM SATUAN | AK7: DLM SATUAN | AM7: DLM SATUAN | AP7: HARI | AQ7: SABTU
E8: Rp | F8: Unit | G8: Rp | H8: Unit | I8: Rp | J8: Unit | K8: Rp | L8: Unit | M8: Rp | N8: Unit | O8: Rp | P8: Unit | Q8: Rp | R8: Unit | S8: Rp | T8: Unit | U8: Rp | V8: Unit | W8: Rp | X8: Unit | Y8: Rp | Z8: Unit | AA8: Rp | AB8: Unit | AC8: Rp | AD8: Unit | AE8: Rp | AF8: Unit | AG8: Rp | AH8: Unit | AI8: Rp | AJ8: Unit | AK8: Rp | AL8: Unit | AM8: Rp | AN8: Unit | AQ8: RP. | AR8: UNIT | AS8: RP. | AT8: UNIT | AU8: RP. | AV8: UNIT | AW8: RP. | AX8: UNIT | AY8: RP. | AZ8: UNIT | BA8: RP. | BB8: UNIT | BC8: RP. | BD8: UNIT
D9: AYAM | AG9: =SUM(AG10,AG11,AG12,AG13,AG14,AG16)+AG18+AG20 -> 7109010 | AP9: AYAM | AQ9: =SUM(AQ10:AQ15) -> 0 | AS9: =SUM(AS10:AS14) -> 0 | AU9: =SUM(AU10:AU14) -> 0 | AW9: =SUM(AW10:AW14) -> 0 | AY9: =SUM(AY10:AY14) -> 0 | BA9: =SUM(BA10:BA14) -> 0 | BC9: =SUM(BC10:BC14) -> 0
C10: 1 | D10: =WEEKLY!B11 -> DADA MENTOK | E10: 730095.93 | F10: 136.8 | G10: 185867.5 | H10: 35 | AC10: =-('TO-TI'!S7+'TO-TI'!D8) -> -78609.375 | AD10: =-('TO-TI'!Q7+'TO-TI'!B8) -> -15 | AG10: ='PEMBELIAN KREDIT'!H32 -> 445453.12 | AH10: ='PEMBELIAN KREDIT'!I32 -> 85 | AI10: =SUM(I10,K10,M10,O10,Q10,S10,U10,W10,Y10,AA10,AC10,AE10,AG10) -> 366843.75 | AJ10: =SUM(J10,L10,N10,P10,R10,T10,V10,X10,Z10,AB10,AD10,AF10,AH10) -> 70 | AK10: =WEEKLY!F11 -> 178181.25 | AL10: =WEEKLY!D11 -> 34 | AM10: =G10+AI10-AK10 -> 374530 | AN10: =H10+AJ10-AL10 -> 71 | AO10: =AM10-E10 -> -355565.93 | AP10: DADA MENTOK
C11: 2 | D11: =WEEKLY!B12 -> DADA | E11: 1471060 | F11: 229 | G11: 379905 | H11: 60 | AC11: =-('TO-TI'!N7+'TO-TI'!I7) -> -120500.97 | AD11: =-('TO-TI'!L7+'TO-TI'!G7) -> -14 | AG11: ='PEMBELIAN KREDIT'!H33 -> 1062234.4 | AH11: ='PEMBELIAN KREDIT'!I33 -> 170 | AI11: =SUM(I11,K11,M11,O11,Q11,S11,U11,W11,Y11,AA11,AC11,AE11,AG11) -> 941733.41 | AJ11: =SUM(J11,L11,N11,P11,R11,T11,V11,X11,Z11,AB11,AD11,AF11,AH11) -> 156 | AK11: =WEEKLY!F12 -> 318670.31 | AL11: =WEEKLY!D12 -> 51 | AM11: =G11+AI11-AK11 -> 1002968.1 | AN11: =H11+AJ11-AL11 -> 165 | AO11: =AM11-E11 -> -468091.89 | AP11: DADA
C12: 3 | D12: =WEEKLY!B13 -> PAHA ATAS | E12: 1638816 | F12: 240 | G12: 300656 | H12: 46 | AC12: =-('TO-TI'!N8+'TO-TI'!I8) -> 0 | AD12: =-('TO-TI'!L8+'TO-TI'!G8) -> 0 | AG12: ='PEMBELIAN KREDIT'!H34 -> 1096500 | AH12: ='PEMBELIAN KREDIT'!I34 -> 170 | AI12: =SUM(I12,K12,M12,O12,Q12,S12,U12,W12,Y12,AA12,AC12,AE12,AG12) -> 1096500 | AJ12: =SUM(J12,L12,N12,P12,R12,T12,V12,X12,Z12,AB12,AD12,AF12,AH12) -> 170 | AK12: =WEEKLY!F13 -> 380550 | AL12: =WEEKLY!D13 -> 59 | AM12: =G12+AI12-AK12 -> 1016606 | AN12: =H12+AJ12-AL12 -> 157 | AO12: =AM12-E12 -> -622210 | AP12: PAHA ATAS
C13: 4 | D13: =WEEKLY!B14 -> PAHA BAWAH | E13: 2222090.6 | F13: 496 | G13: 540241.25 | H13: 115 | AC13: =-('TO-TI'!N9+'TO-TI'!I9) -> 0 | AD13: =-('TO-TI'!L9+'TO-TI'!G9) -> 0 | AG13: ='PEMBELIAN KREDIT'!H35+'PEMBELIAN KREDIT'!H39 -> 1080709.4 | AH13: ='PEMBELIAN KREDIT'!I35+'PEMBELIAN KREDIT'!I39 -> 240 | AI13: =SUM(I13,K13,M13,O13,Q13,S13,U13,W13,Y13,AA13,AC13,AE13,AG13) -> 1080709.4 | AJ13: =SUM(J13,L13,N13,P13,R13,T13,V13,X13,Z13,AB13,AD13,AF13,AH13) -> 240 | AK13: =WEEKLY!F14 -> 593400 | AL13: =WEEKLY!D14 -> 128 | AM13: =G13+AI13-AK13 -> 1027550.6 | AN13: =H13+AJ13-AL13 -> 227 | AO13: =AM13-E13 -> -1194540 | AP13: PAHA BAWAH
B14: A | C14: 5 | D14: =WEEKLY!B15 -> SAYAP | E14: 2370220.6 | F14: 674 | G14: 784932.75 | H14: 183 | AC14: =-('TO-TI'!N10+'TO-TI'!I10) -> 0 | AD14: =-('TO-TI'!L10+'TO-TI'!G10) -> 0 | AG14: ='PEMBELIAN KREDIT'!H36+'PEMBELIAN KREDIT'!H37 -> 924888.12 | AH14: ='PEMBELIAN KREDIT'!I36+'PEMBELIAN KREDIT'!I37 -> 240 | AI14: =SUM(I14,K14,M14,O14,Q14,S14,U14,W14,Y14,AA14,AC14,AE14,AG14) -> 924888.12 | AJ14: =SUM(J14,L14,N14,P14,R14,T14,V14,X14,Z14,AB14,AD14,AF14,AH14) -> 240 | AK14: =WEEKLY!F15 -> 576642.5 | AL14: =WEEKLY!D15 -> 136 | AM14: =G14+AI14-AK14 -> 1133178.4 | AN14: =H14+AJ14-AL14 -> 287 | AO14: =AM14-E14 -> -1237042.2 | AP14: SAYAP
B15: Y | C15: 6 | D15: =WEEKLY!B16 -> CHICKEN PATTY | E15: 134783.75 | F15: 49 | G15: 46761.708 | H15: 17 | AC15: ='TO-TI'!S19 -> 85485.875 | AD15: ='TO-TI'!Q21 -> 36 | AI15: =SUM(I15,K15,M15,O15,Q15,S15,U15,W15,Y15,AA15,AC15,AE15,AG15) -> 85485.875 | AJ15: =SUM(J15,L15,N15,P15,R15,T15,V15,X15,Z15,AB15,AD15,AF15,AH15) -> 36 | AK15: =WEEKLY!F16 -> 52241.368 | AL15: =WEEKLY!D16 -> 22 | AM15: =G15+AI15-AK15 -> 80006.214 | AN15: =H15+AJ15-AL15 -> 31 | AO15: =AM15-E15 -> -54777.531 | AP15: MARINADE
B16: A | C16: 7 | D16: =WEEKLY!B17 -> AYAM WHOLE | E16: 3327750 | F16: 135 | G16: 1084600 | H16: 44 | AG16: ='PEMBELIAN KREDIT'!H41 -> 1925600 | AH16: ='PEMBELIAN KREDIT'!I41 -> 80 | AI16: =SUM(I16,K16,M16,O16,Q16,S16,U16,W16,Y16,AA16,AC16,AE16,AG16) -> 1925600 | AJ16: =SUM(J16,L16,N16,P16,R16,T16,V16,X16,Z16,AB16,AD16,AF16,AH16) -> 80 | AK16: =WEEKLY!F17 -> 625820 | AL16: =WEEKLY!D17 -> 26 | AM16: =G16+AI16-AK16 -> 2384380 | AN16: =H16+AJ16-AL16 -> 98
B17: M | C17: 8 | D17: =WEEKLY!B18 -> SAYAP FULL | E17: 0 | F17: 0 | G17: 0 | H17: 0 | AI17: =SUM(I17,K17,M17,O17,Q17,S17,U17,W17,Y17,AA17,AC17,AE17,AG17) -> 0 | AJ17: =SUM(J17,L17,N17,P17,R17,T17,V17,X17,Z17,AB17,AD17,AF17,AH17) -> 0 | AK17: =WEEKLY!F18 -> 0 | AL17: =WEEKLY!D18 -> 0 | AM17: =G17+AI17-AK17 -> 0 | AN17: =H17+AJ17-AL17 -> 0
C18: 9 | D18: =WEEKLY!B19 -> KULIT | E18: 612675 | F18: 17.35 | G18: 351450 | H18: 9.9 | AG18: ='PEMBELIAN KREDIT'!H38 -> 369250 | AH18: ='PEMBELIAN KREDIT'!I38 -> 10.55 | AI18: =SUM(I18,K18,M18,O18,Q18,S18,U18,W18,Y18,AA18,AC18,AE18,AG18) -> 369250 | AJ18: =SUM(J18,L18,N18,P18,R18,T18,V18,X18,Z18,AB18,AD18,AF18,AH18) -> 10.55 | AK18: =WEEKLY!F19 -> 266250 | AL18: =WEEKLY!D19 -> 7.5 | AM18: =G18+AI18-AK18 -> 454450 | AN18: =H18+AJ18-AL18 -> 12.95
C19: 10 | D19: =WEEKLY!B20 -> PAHA BAWAH FULL | E19: 0 | F19: 0 | G19: 0 | H19: 0 | AI19: =SUM(I19,K19,M19,O19,Q19,S19,U19,W19,Y19,AA19,AC19,AE19,AG19) -> 0 | AJ19: =SUM(J19,L19,N19,P19,R19,T19,V19,X19,Z19,AB19,AD19,AF19,AH19) -> 0 | AK19: =WEEKLY!F20 -> 0 | AL19: =WEEKLY!D20 -> 0 | AM19: =G19+AI19-AK19 -> 0 | AN19: =H19+AJ19-AL19 -> 0
C20: 11 | D20: =WEEKLY!B21 -> CUT 10 | E20: 326780 | F20: 80 | G20: 1076920 | H20: 260 | AG20: ='PEMBELIAN KREDIT'!H40 -> 204375 | AH20: ='PEMBELIAN KREDIT'!I40 -> 50 | AI20: =SUM(I20,K20,M20,O20,Q20,S20,U20,W20,Y20,AA20,AC20,AE20,AG20) -> 204375 | AJ20: =SUM(J20,L20,N20,P20,R20,T20,V20,X20,Z20,AB20,AD20,AF20,AH20) -> 50 | AK20: =WEEKLY!F21 -> 994080 | AL20: =WEEKLY!D21 -> 240 | AM20: =G20+AI20-AK20 -> 287215 | AN20: =H20+AJ20-AL20 -> 70
C21: 12 | D21: =WEEKLY!B22 -> 0 | E21: 0 | F21: 0 | G21: 0 | H21: 0 | AI21: =SUM(I21,K21,M21,O21,Q21,S21,U21,W21,Y21,AA21,AC21,AE21,AG21) -> 0 | AJ21: =SUM(J21,L21,N21,P21,R21,T21,V21,X21,Z21,AB21,AD21,AF21,AH21) -> 0 | AK21: =WEEKLY!F22 -> 0 | AL21: =WEEKLY!D22 -> 0 | AM21: =G21+AI21-AK21 -> 0 | AN21: =H21+AJ21-AL21 -> 0
C22: 13 | D22: =WEEKLY!B23 -> 0 | E22: 0 | F22: 0 | G22: 0 | H22: 0 | AI22: =SUM(I22,K22,M22,O22,Q22,S22,U22,W22,Y22,AA22,AC22,AE22,AG22) -> 0 | AJ22: =SUM(J22,L22,N22,P22,R22,T22,V22,X22,Z22,AB22,AD22,AF22,AH22) -> 0 | AK22: =WEEKLY!F23 -> 0 | AL22: =WEEKLY!D23 -> 0 | AM22: =G22+AI22-AK22 -> 0 | AN22: =H22+AJ22-AL22 -> 0
C23: 14 | D23: =WEEKLY!B24 -> 0 | E23: 0 | F23: 0 | G23: 0 | H23: 0 | AI23: =SUM(I23,K23,M23,O23,Q23,S23,U23,W23,Y23,AA23,AC23,AE23,AG23) -> 0 | AJ23: =SUM(J23,L23,N23,P23,R23,T23,V23,X23,Z23,AB23,AD23,AF23,AH23) -> 0 | AK23: =WEEKLY!F24 -> 0 | AL23: =WEEKLY!D24 -> 0 | AM23: =G23+AI23-AK23 -> 0 | AN23: =H23+AJ23-AL23 -> 0 | AO23: AYAM | AP23: =SUM(AM10:AM23) -> 7760884.3
C24: 1 | D24: =WEEKLY!B27 -> VEGETABLE MIX | E24: 11200 | F24: 0.32 | G24: 35000 | H24: 1 | AI24: =SUM(I24,K24,M24,O24,Q24,S24,U24,W24,Y24,AA24,AC24,AE24,AG24) -> 0 | AJ24: =SUM(J24,L24,N24,P24,R24,T24,V24,X24,Z24,AB24,AD24,AF24,AH24) -> 0 | AK24: =WEEKLY!F27 -> 21000 | AL24: =WEEKLY!D27 -> 0.6 | AM24: =G24+AI24-AK24 -> 14000 | AN24: =H24+AJ24-AL24 -> 0.4 | AO24: =AM24-E24 -> 2800
B25: P | C25: 2 | D25: =WEEKLY!B28 -> BERAS | E25: 2197408.2 | F25: 137.53333 | G25: 2135000 | H25: 122 | AC25: =-('TO-TI'!N11+'TO-TI'!I11) -> -40166.99 | AD25: =-('TO-TI'!L11+'TO-TI'!G11)/15 -> -0.93333333 | AG25: ='PEMBELIAN KREDIT'!G13 -> 2905000 | AH25: 175 | AI25: =SUM(I25,K25,M25,O25,Q25,S25,U25,W25,Y25,AA25,AC25,AE25,AG25) -> 2864833 | AJ25: =SUM(J25,L25,N25,P25,R25,T25,V25,X25,Z25,AB25,AD25,AF25,AH25) -> 174.06667 | AK25: =WEEKLY!F28 -> 3885000 | AL25: =WEEKLY!D28 -> 222 | AM25: =G25+AI25-AK25 -> 1114833 | AN25: =H25+AJ25-AL25 -> 74.066667 | AO25: =AM25-E25 -> -1082575.2
B26: E | C26: 3 | D26: =WEEKLY!B29 -> FRENCH FRIES | E26: 105000 | F26: 2.3 | G26: 30000 | H26: 1 | I26: 84000 | J26: 2 | AI26: =SUM(I26,K26,M26,O26,Q26,S26,U26,W26,Y26,AA26,AC26,AE26,AG26) -> 84000 | AJ26: =SUM(J26,L26,N26,P26,R26,T26,V26,X26,Z26,AB26,AD26,AF26,AH26) -> 2 | AK26: =WEEKLY!F29 -> 12000 | AL26: =WEEKLY!D29 -> 0.4 | AM26: =G26+AI26-AK26 -> 102000 | AN26: =H26+AJ26-AL26 -> 2.6 | AO26: =AM26-E26 -> -3000
B27: L | C27: 4 | D27: =WEEKLY!B30 -> ROTI BURGER | E27: 141833 | F27: 49 | G27: 28330 | H27: 10 | K27: 34000 | L27: 12 | Q27: 36000 | R27: 12 | AI27: =SUM(I27,K27,M27,O27,Q27,S27,U27,W27,Y27,AA27,AC27,AE27,AG27) -> 70000 | AJ27: =SUM(J27,L27,N27,P27,R27,T27,V27,X27,Z27,AB27,AD27,AF27,AH27) -> 24 | AK27: =WEEKLY!F30 -> 8499 | AL27: =WEEKLY!D30 -> 3 | AM27: =G27+AI27-AK27 -> 89831 | AN27: =H27+AJ27-AL27 -> 31 | AO27: =AM27-E27 -> -52002
B28: E | C28: 5 | D28: =WEEKLY!B31 -> SOSIS | E28: 5200 | F28: 4 | G28: 18200 | H28: 14 | AI28: =SUM(I28,K28,M28,O28,Q28,S28,U28,W28,Y28,AA28,AC28,AE28,AG28) -> 0 | AJ28: =SUM(J28,L28,N28,P28,R28,T28,V28,X28,Z28,AB28,AD28,AF28,AH28) -> 0 | AK28: =WEEKLY!F31 -> 13000 | AL28: =WEEKLY!D31 -> 10 | AM28: =G28+AI28-AK28 -> 5200 | AN28: =H28+AJ28-AL28 -> 4 | AO28: =AM28-E28 -> 0
B29: N | C29: 6 | D29: =WEEKLY!B32 -> PERKEDEL | E29: 101905.72 | F29: 47 | G29: 84308.161 | H29: 34 | AC29: ='TO-TI'!D18 -> 139420.5 | AD29: ='TO-TI'!B20 -> 72 | AI29: =SUM(I29,K29,M29,O29,Q29,S29,U29,W29,Y29,AA29,AC29,AE29,AG29) -> 139420.5 | AJ29: =SUM(J29,L29,N29,P29,R29,T29,V29,X29,Z29,AB29,AD29,AF29,AH29) -> 72 | AK29: =WEEKLY!F32 -> 109104.68 | AL29: =WEEKLY!D32 -> 44 | AM29: =G29+AI29-AK29 -> 114623.98 | AN29: =H29+AJ29-AL29 -> 62 | AO29: =AM29-E29 -> 12718.259
B30: G | C30: 7 | D30: =WEEKLY!B33 -> SOSIS NASGOR | E30: -12650 | F30: -11 | G30: 12650 | H30: 11 | K30: 30000 | L30: 35 | AI30: =SUM(I30,K30,M30,O30,Q30,S30,U30,W30,Y30,AA30,AC30,AE30,AG30) -> 30000 | AJ30: =SUM(J30,L30,N30,P30,R30,T30,V30,X30,Z30,AB30,AD30,AF30,AH30) -> 35 | AK30: =WEEKLY!F33 -> 10350 | AL30: =WEEKLY!D33 -> 9 | AM30: =G30+AI30-AK30 -> 32300 | AN30: =H30+AJ30-AL30 -> 37 | AO30: =AM30-E30 -> 44950
B31: K | C31: 8 | D31: =WEEKLY!B34 -> NUGGET COIN | E31: 30400 | F31: 4 | G31: 28800 | H31: 48 | AI31: =SUM(I31,K31,M31,O31,Q31,S31,U31,W31,Y31,AA31,AC31,AE31,AG31) -> 0 | AJ31: =SUM(J31,L31,N31,P31,R31,T31,V31,X31,Z31,AB31,AD31,AF31,AH31) -> 0 | AK31: =WEEKLY!F34 -> 28800 | AL31: =WEEKLY!D34 -> 48 | AM31: =G31+AI31-AK31 -> 0 | AN31: =H31+AJ31-AL31 -> 0 | AO31: =AM31-E31 -> -30400
B32: A | C32: 9 | D32: =WEEKLY!B35 -> BAKSO | E32: 8320 | F32: 13 | G32: 2560 | H32: 4 | AI32: =SUM(I32,K32,M32,O32,Q32,S32,U32,W32,Y32,AA32,AC32,AE32,AG32) -> 0 | AJ32: =SUM(J32,L32,N32,P32,R32,T32,V32,X32,Z32,AB32,AD32,AF32,AH32) -> 0 | AK32: =WEEKLY!F35 -> 2560 | AL32: =WEEKLY!D35 -> 4 | AM32: =G32+AI32-AK32 -> 0 | AN32: =H32+AJ32-AL32 -> 0 | AO32: =AM32-E32 -> -8320
B33: P | C33: 10 | D33: =WEEKLY!B36 -> 0 | E33: 0 | F33: 0 | G33: 0 | H33: 0 | AI33: =SUM(I33,K33,M33,O33,Q33,S33,U33,W33,Y33,AA33,AC33,AE33,AG33) -> 0 | AJ33: =SUM(J33,L33,N33,P33,R33,T33,V33,X33,Z33,AB33,AD33,AF33,AH33) -> 0 | AK33: =WEEKLY!F36 -> 0 | AL33: =WEEKLY!D36 -> 0 | AM33: =G33+AI33-AK33 -> 0 | AN33: =H33+AJ33-AL33 -> 0 | AO33: =AM33-E33 -> 0
C34: 11 | D34: =WEEKLY!B37 -> 0 | E34: 0 | F34: 0 | G34: 0 | H34: 0 | AI34: =SUM(I34,K34,M34,O34,Q34,S34,U34,W34,Y34,AA34,AC34,AE34,AG34) -> 0 | AJ34: =SUM(J34,L34,N34,P34,R34,T34,V34,X34,Z34,AB34,AD34,AF34,AH34) -> 0 | AK34: =WEEKLY!F37 -> 0 | AL34: =WEEKLY!D37 -> 0 | AM34: =G34+AI34-AK34 -> 0 | AN34: =H34+AJ34-AL34 -> 0 | AO34: =AM34-E34 -> 0
C35: 12 | D35: =WEEKLY!B38 -> 0 | E35: 0 | F35: 0 | G35: 0 | H35: 0 | AI35: =SUM(I35,K35,M35,O35,Q35,S35,U35,W35,Y35,AA35,AC35,AE35,AG35) -> 0 | AJ35: =SUM(J35,L35,N35,P35,R35,T35,V35,X35,Z35,AB35,AD35,AF35,AH35) -> 0 | AK35: =WEEKLY!F38 -> 0 | AL35: =WEEKLY!D38 -> 0 | AM35: =G35+AI35-AK35 -> 0 | AN35: =H35+AJ35-AL35 -> 0 | AO35: =AM35-E35 -> 0
C36: 13 | D36: BAHAN ROTI | E36: 43182.933 | F36: 0 | G36: 109802.13 | I36: 23000 | K36: 35000 | M36: 15000 | U36: 26900 | AC36: =-('TO-TI'!S10+'TO-TI'!S11+'TO-TI'!S12+'TO-TI'!S14) -> -3950 | AI36: =SUM(I36,K36,M36,O36,Q36,S36,U36,W36,Y36,AA36,AC36,AE36,AG36) -> 95950 | AJ36: =SUM(J36,L36,N36,P36,R36,T36,V36,X36,Z36,AB36,AD36,AF36,AH36) -> 0 | AK36: =WEEKLY!I54 -> 70828.533 | AM36: =G36+AI36-AK36 -> 134923.6 | AN36: =H36+AJ36-AL36 -> 0 | AO36: =AM36-E36 -> 91740.667
C37: 14 | E37: 0 | F37: 0 | AI37: =SUM(I37,K37,M37,O37,Q37,S37,U37,W37,Y37,AA37,AC37,AE37,AG37) -> 0 | AJ37: =SUM(J37,L37,N37,P37,R37,T37,V37,X37,Z37,AB37,AD37,AF37,AH37) -> 0 | AM37: =G37+AI37-AK37 -> 0 | AN37: =H37+AJ37-AL37 -> 0 | AO37: PELENGKAP | AP37: =SUM(AM24:AM37) -> 1607711.6
B38: BA | C38: 1 | D38: =WEEKLY!B57 -> GULA PASIR | E38: 748000 | F38: 0 | G38: 0 | H38: 0 | I38: 100000 | K38: 100000 | O38: 350000 | U38: 262500 | AI38: =SUM(I38,K38,M38,O38,Q38,S38,U38,W38,Y38,AA38,AC38,AE38,AG38) -> 812500 | AJ38: =SUM(J38,L38,N38,P38,R38,T38,V38,X38,Z38,AB38,AD38,AF38,AH38) -> 0 | AK38: =WEEKLY!F57 -> 0 | AL38: =WEEKLY!D57 -> 0 | AM38: =G38+AI38-AK38 -> 812500 | AN38: =H38+AJ38-AL38 -> 0 | AO38: =AM38-E38 -> 64500
B39: HA | C39: 2 | D39: =WEEKLY!B58 -> 0 | E39: 0 | F39: 0 | G39: 0 | H39: 0 | AI39: =SUM(I39,K39,M39,O39,Q39,S39,U39,W39,Y39,AA39,AC39,AE39,AG39) -> 0 | AJ39: =SUM(J39,L39,N39,P39,R39,T39,V39,X39,Z39,AB39,AD39,AF39,AH39) -> 0 | AK39: =WEEKLY!F58 -> 0 | AL39: =WEEKLY!D58 -> 0 | AM39: =G39+AI39-AK39 -> 0 | AN39: =H39+AJ39-AL39 -> 0
B40: N | C40: 3 | D40: =WEEKLY!B59 -> ICE CREAM EMBER | E40: 0 | F40: 0 | G40: 0 | H40: 0 | AI40: =SUM(I40,K40,M40,O40,Q40,S40,U40,W40,Y40,AA40,AC40,AE40,AG40) -> 0 | AJ40: =SUM(J40,L40,N40,P40,R40,T40,V40,X40,Z40,AB40,AD40,AF40,AH40) -> 0 | AK40: =WEEKLY!F59 -> 13750 | AL40: =WEEKLY!D59 -> 0.5 | AM40: =G40+AI40-AK40 -> -13750 | AN40: =H40+AJ40-AL40 -> -0.5
B41: ES | C41: 4 | D41: BAHAN ES | E41: 568868.42 | F41: 0 | G41: 102631.58 | I41: 70000 | M41: 70000 | Q41: 70000 | S41: 45000 | U41: 24000 | AI41: =SUM(I41,K41,M41,O41,Q41,S41,U41,W41,Y41,AA41,AC41,AE41,AG41) -> 279000 | AJ41: =SUM(J41,L41,N41,P41,R41,T41,V41,X41,Z41,AB41,AD41,AF41,AH41) -> 0 | AK41: =WEEKLY!I69 -> 534133.33 | AM41: =G41+AI41-AK41 -> -152501.75 | AN41: =H41+AJ41-AL41 -> 0 | AO41: DESSERT | AP41: =SUM(AM38:AM41) -> 646248.25
C43: 1 | D43: =WEEKLY!B76 -> TEH BOTOL SOSRO (TBS) | E43: 75000 | F43: 30 | G43: 72500 | H43: 29 | AI43: =SUM(I43,K43,M43,O43,Q43,S43,U43,W43,Y43,AA43,AC43,AE43,AG43) -> 0 | AJ43: =SUM(J43,L43,N43,P43,R43,T43,V43,X43,Z43,AB43,AD43,AF43,AH43) -> 0 | AK43: =WEEKLY!F76 -> 37500 | AL43: =WEEKLY!D76 -> 15 | AM43: =G43+AI43-AK43 -> 35000 | AN43: =H43+AJ43-AL43 -> 14 | AO43: =AM43-E43 -> -40000
...

Sheet WEEKLY
A3: WEEKLY / MONTHLY INVENTORI
E5: Cabang : | F5: =LPKK!Q4 -> SC MARABAHAN
E6: Periode : | F6: =LPKK!Q5 -> 1-7 JULI 2026
A9: NO | B9: BAHAN | C9: UNIT | D9: QTY | E9: PRICE | F9: TOTAL (Rp)
A10: I | B10: BAHAN AYAM
A11: 1 | B11: DADA MENTOK | C11: Pcs | D11: 34 | E11: 5240.625 | F11: =D11*E11 -> 178181.25
A12: 2 | B12: DADA | C12: Pcs | D12: 51 | E12: 6248.4375 | F12: =D12*E12 -> 318670.31
A13: 3 | B13: PAHA ATAS | C13: Pcs | D13: 59 | E13: 6450 | F13: =D13*E13 -> 380550
A14: 4 | B14: PAHA BAWAH | C14: Pcs | D14: 128 | E14: 4635.9375 | F14: =D14*E14 -> 593400
A15: 5 | B15: SAYAP | C15: Pcs | D15: 136 | E15: 4240.0184 | F15: =D15*E15 -> 576642.5
A16: 6 | B16: CHICKEN PATTY | C16: Pcs | D16: 22 | E16: ='TO-TI'!S21 -> 2374.6076 | F16: =D16*E16 -> 52241.368
A17: 7 | B17: AYAM WHOLE | C17: Pcs | D17: 26 | E17: 24070 | F17: =D17*E17 -> 625820
A18: 8 | B18: SAYAP FULL | C18: Pcs | E18: 3172.75 | F18: =D18*E18 -> 0
A19: 9 | B19: KULIT | C19: Kg | D19: 7.5 | E19: 35500 | F19: =D19*E19 -> 266250
A20: 10 | B20: PAHA BAWAH FULL | C20: Pcs | E20: 4647.98 | F20: =D20*E20 -> 0
A21: 11 | B21: CUT 10 | C21: Pcs | D21: 240 | E21: 4142 | F21: =D21*E21 -> 994080
A22: 12 | F22: =D22*E22 -> 0
A23: 13 | F23: =D23*E23 -> 0
A24: 14 | F24: =D24*E24 -> 0
E25: JUMLAH | F25: =SUM(F11:F24) -> 3985835.4
A26: II | B26: BAHAN PELENGKAP
A27: 1 | B27: VEGETABLE MIX | C27: Kg | D27: 0.6 | E27: 35000 | F27: =D27*E27 -> 21000
A28: 2 | B28: BERAS | C28: Kg | D28: 222 | E28: 17500 | F28: =D28*E28 -> 3885000
A29: 3 | B29: FRENCH FRIES | C29: Kg | D29: 0.4 | E29: 30000 | F29: =D29*E29 -> 12000
A30: 4 | B30: ROTI BURGER | C30: Pcs | D30: 3 | E30: 2833 | F30: =D30*E30 -> 8499
A31: 5 | B31: SOSIS | C31: Pcs | D31: 10 | E31: 1300 | F31: =D31*E31 -> 13000
A32: 6 | B32: PERKEDEL | C32: pcs | D32: 44 | E32: 2479.6518 | F32: =D32*E32 -> 109104.68
A33: 7 | B33: SOSIS NASGOR | C33: Pcs | D33: 9 | E33: 1150 | F33: =D33*E33 -> 10350
A34: 8 | B34: NUGGET COIN | C34: Pcs | D34: 48 | E34: 600 | F34: =D34*E34 -> 28800
A35: 9 | B35: BAKSO | C35: Pcs | D35: 4 | E35: 640 | F35: =D35*E35 -> 2560
A36: 10 | F36: =D36*E36 -> 0
A37: 11 | F37: =D37*E37 -> 0
A38: 12 | F38: =D38*E38 -> 0
B39: BAHAN ROTI
A40: 13 | B40: SLICED CHEESE | C40: Pcs | D40: 17 | E40: 1166 | F40: =D40*E40 -> 19822
A41: 14 | B41: KEJU BATANG (170 GR ) | C41: Pack | D41: 1 | E41: 17000 | F41: =D41*E41 -> 17000
A42: 15 | B42: TEPUNG ROTI (PANIR) | C42: Kg | D42: 0.13 | E42: 31000 | F42: =D42*E42 -> 4030
A43: 16 | B43: CUKA DIXI 150 ML | C43: Botol | D43: 1 | E43: 5000 | F43: =D43*E43 -> 5000
A44: 17 | B44: BAWANG BOMBAY | C44: Kg | D44: 0.1 | E44: 40000 | F44: =D44*E44 -> 4000
A45: 18 | B45: DRESSING BURGER | C45: Resep | D45: 0.2 | E45: 37882.667 | F45: =D45*E45 -> 7576.5333
...

Sheet LAP. CF
A4: LAPORAN CASH FLOW
H6: Periode : | I6: =LPKK!Q5 -> 1-7 JULI 2026
H7: CABANG : | I7: =LPKK!Q4 -> SC MARABAHAN
A8: SALDO AWAL PER ………………………..
A10: Penerimaan : | J10: Rp. | K10: 1589512
B11: Sales tanggal, | D11: ='LAPORAN KAS PERIODE'!$D$6 -> 1-Juli-2026 | G11: Rp. | H11: ='LAPORAN KAS PERIODE'!$D$15 -> 4454000
B12: Sales tanggal, | D12: ='LAPORAN KAS PERIODE'!$E$6 -> 2-Juli-2026 | G12: Rp. | H12: ='LAPORAN KAS PERIODE'!$E$15 -> 3639000
B13: Sales tanggal, | D13: ='LAPORAN KAS PERIODE'!$F$6 -> 3-Juli-2026 | G13: Rp. | H13: ='LAPORAN KAS PERIODE'!$F$15 -> 3173500
B14: Sales tanggal, | D14: ='LAPORAN KAS PERIODE'!$G$6 -> 4-Juli-2026 | G14: Rp. | H14: ='LAPORAN KAS PERIODE'!$G$15 -> 3484000
B15: Sales tanggal, | D15: ='LAPORAN KAS PERIODE'!$H$6 -> 5-Juli-2026 | G15: Rp. | H15: ='LAPORAN KAS PERIODE'!$H$15 -> 4920500
B16: Sales tanggal, | D16: ='LAPORAN KAS PERIODE'!$I$6 -> 6-Juli-2026 | G16: Rp. | H16: ='LAPORAN KAS PERIODE'!$I$15 -> 4009000
B17: Sales tanggal, | D17: ='LAPORAN KAS PERIODE'!$J$6 -> 7-Juli-2026 | G17: Rp. | H17: ='LAPORAN KAS PERIODE'!$J$15 -> 3711500
B18: Sales tanggal, | D18: ='LAPORAN KAS PERIODE'!$K$6 -> 0 | G18: Rp. | H18: ='LAPORAN KAS PERIODE'!$K$15 -> 0
B19: Sales tanggal, | D19: ='LAPORAN KAS PERIODE'!$L$6 -> 0 | G19: Rp. | H19: ='LAPORAN KAS PERIODE'!$L$15 -> 0
B20: Sales tanggal, | D20: ='LAPORAN KAS PERIODE'!$M$6 -> 0 | G20: Rp. | H20: ='LAPORAN KAS PERIODE'!$M$15 -> 0
D23: Total Penerimaan Sales | H23: ….................................. | J23: Rp. | K23: =SUM(H11:I20) -> 27391500
A25: Penerimaan Lain - lain :
B26: MIKAS OWNER | G26: Rp | H26: 663000
G27: Rp
G28: Rp
G29: Rp
G30: Rp
H32: ….................................... | J32: Rp. | K32: =SUM(H26:I30) -> 663000
D34: Total Uang Yang Ada | H34: …................................... | J34: Rp. | K34: =K10+K23+K32 -> 29644012
A35: Pengeluaran :
B37: Belanja Tgl | D37: =D11 -> 1-Juli-2026 | G37: Rp. | H37: =VENDOR!I216 -> 1994000
B38: Belanja Tgl | D38: =D12 -> 2-Juli-2026 | G38: Rp. | H38: =VENDOR!K216 -> 1985500
B39: Belanja Tgl | D39: =D13 -> 3-Juli-2026 | G39: Rp. | H39: =VENDOR!M216 -> 4009438
B40: Belanja Tgl | D40: =D14 -> 4-Juli-2026 | G40: Rp. | H40: =VENDOR!O216 -> 2489000
B41: Belanja Tgl | D41: =D15 -> 5-Juli-2026 | G41: Rp. | H41: =VENDOR!Q216 -> 6584925
B42: Belanja Tgl | D42: =D16 -> 6-Juli-2026 | G42: Rp. | H42: =VENDOR!S216 -> 3270500
B43: Belanja Tgl | D43: =D17 -> 7-Juli-2026 | G43: Rp. | H43: =VENDOR!U216 -> 3709202
B44: Belanja Tgl | D44: =D18 -> 0 | G44: Rp. | H44: =VENDOR!W216 -> 0
B45: Belanja Tgl | D45: =D19 -> 0 | G45: Rp. | H45: =VENDOR!Y216 -> 0
B46: Belanja Tgl | D46: =D20 -> 0 | G46: Rp. | H46: =VENDOR!AA216 -> 0
D50: Total Pengeluaran | H50: …................................... | J50: Rp. | K50: =SUM(H37:I47) -> 24042565
A52: SALDO AKHIR PER ………………….. | H52: …................................... | J52: Rp. | K52: =K34-K50 -> 5601447
B55: Paraf Supervisor

Sheet IKHTISAR FOOD COST
A2: LAPORAN IKHTISAR FOOD COST
C5: CABANG : | D5: =LPKK!Q4 -> SC MARABAHAN
C6: PERIODE: | D6: =LPKK!Q5 -> 1-7 JULI 2026
B8: FOOD & BEVERAGE | D8: PAPER
A10: PERSEDIAAN AWAL | B10: 12327192 | D10: 2273313.6
A12: TRANSFER IN (+) =
A13: C. PATTY | B13: ='TO-TI'!S19 -> 85485.875
A14: PERKEDEL | B14: ='TO-TI'!D18 -> 139420.5
A16: TOTAL TRANSFER IN | B16: =SUM(B12:B14) -> 224906.38 | D16: =SUM(D12:D14) -> 0
A18: PEMBELIAN
A19: PEMBELIAN KREDIT | B19: =VENDOR!AI153 -> 12120878 | D19: =VENDOR!AI154 -> 6579650
A20: PEMBELIAN KONTAN | B20: =VENDOR!AI155 -> 2809438 | D20: =VENDOR!AI156 -> 421900
A21: TOTAL PEMBELIAN | B21: =B19+B20 -> 14930316 | D21: =D19+D20 -> 7001550
A23: JUMLAH YANG TERSEDIA | B23: =B10+B16+B21 -> 27482414 | D23: =D10+D16+D21 -> 9274863.6
A25: TRANSFER OUT (-) =
A26: TO CATERING STAFF / FREE | B26: ='TO-TI'!I20+'TO-TI'!N21 -> 160667.96
A27: C. PATTY | B27: ='TO-TI'!S19 -> 85485.875
A28: PERKEDEL | B28: ='TO-TI'!D18 -> 139420.5
A31: TOTAL TRANSFER OUT | B31: =SUM(B26:B29) -> 385574.33 | D31: =SUM(D26:D29) -> 0
A33: PERSEDIAAN AKHIR | B33: =WEEKLY!F333 -> 14070978 | D33: =WEEKLY!F334 -> 6867740.4
A35: JUMLAH YANG DIPAKAI | B35: =B23-B31-B33 -> 13025862 | D35: =D23-D31-D33 -> 2407123.2
A36: (%) | B36: =(B35/B44) -> 0.47554394 | D36: =D35/B44 -> 0.087878473
A39: PENJUALAN KOTOR | B39: ='LAPORAN KAS PERIODE'!N8 -> 27391500
A40: KOREKSI (-) | B40: ='LAPORAN KAS PERIODE'!N12 -> 0
A41: DISCOUNT (-) | B41: ='LAPORAN KAS PERIODE'!N13 -> 0
A42: KOMISI PENJUALAN ONLINE (-) | B42: =SUM('LAPORAN KAS PERIODE'!N9:N11) -> 0
A43: TAX ( - )
A44: PENJUALAN BERSIH | B44: =B39-B40-B41-B42-B43 -> 27391500
A47: JUMLAH BAHAN YANG DIPAKAI | B47: =B35+D35 -> 15432985 | D47: =B47/B48 -> 0.56342241
A48: JUMLAH PENJUALAN BERSIH | B48: =B44 -> 27391500

Sheet LAPORAN KAS PERIODE
B2: LAPORAN KAS & PENJUALAN PER PERIODE
L3: CABANG : | M3: =LPKK!Q4 -> SC MARABAHAN
L4: PERIODE : | M4: =LPKK!Q5 -> 1-7 JULI 2026
B6: TANGGAL | D6: 1-Juli-2026 | E6: 2-Juli-2026 | F6: 3-Juli-2026 | G6: 4-Juli-2026 | H6: 5-Juli-2026 | I6: 6-Juli-2026 | J6: 7-Juli-2026 | N6: TOTAL
B7: HARI | D7: Rabu | E7: Kamis | F7: Jum`at | G7: Sabtu | H7: Minggu | I7: Senin | J7: Selasa
B8: Penjualan Kotor | D8: =SUM('LAP. PENJUALAN REGULER'!D112,'LAP. PENJUALAN GOFOOD'!D112,'LAP. PENJUALAN GRABFOOD'!D112,'LAP. PENJUALAN SHOPEFOOD'!D112) -> 4454000 | E8: =SUM('LAP. PENJUALAN REGULER'!E112,'LAP. PENJUALAN GOFOOD'!E112,'LAP. PENJUALAN GRABFOOD'!E112,'LAP. PENJUALAN SHOPEFOOD'!E112) -> 3639000 | F8: =SUM('LAP. PENJUALAN REGULER'!F112,'LAP. PENJUALAN GOFOOD'!F112,'LAP. PENJUALAN GRABFOOD'!F112,'LAP. PENJUALAN SHOPEFOOD'!F112) -> 3173500 | G8: =SUM('LAP. PENJUALAN REGULER'!G112,'LAP. PENJUALAN GOFOOD'!G112,'LAP. PENJUALAN GRABFOOD'!G112,'LAP. PENJUALAN SHOPEFOOD'!G112) -> 3484000 | H8: =SUM('LAP. PENJUALAN REGULER'!H112,'LAP. PENJUALAN GOFOOD'!H112,'LAP. PENJUALAN GRABFOOD'!H112,'LAP. PENJUALAN SHOPEFOOD'!H112) -> 4920500 | I8: =SUM('LAP. PENJUALAN REGULER'!I112,'LAP. PENJUALAN GOFOOD'!I112,'LAP. PENJUALAN GRABFOOD'!I112,'LAP. PENJUALAN SHOPEFOOD'!I112) -> 4009000 | J8: =SUM('LAP. PENJUALAN REGULER'!J112,'LAP. PENJUALAN GOFOOD'!J112,'LAP. PENJUALAN GRABFOOD'!J112,'LAP. PENJUALAN SHOPEFOOD'!J112) -> 3711500 | K8: =SUM('LAP. PENJUALAN REGULER'!K112,'LAP. PENJUALAN GOFOOD'!K112,'LAP. PENJUALAN GRABFOOD'!K112,'LAP. PENJUALAN SHOPEFOOD'!K112) -> 0 | ... M8: =SUM('LAP. PENJUALAN REGULER'!M112,'LAP. PENJUALAN GOFOOD'!M112,'LAP. PENJUALAN GRABFOOD'!M112,'LAP. PENJUALAN SHOPEFOOD'!M112) -> 0 | N8: =SUM(D8:M8) -> 27391500
B9: Komisi grab food | N9: =SUM(D9:M9) -> 0
B10: Komisi gofood | N10: =SUM(D10:M10) -> 0
B11: Komisi shopee food | N11: =SUM(D11:M11) -> 0
B12: Koreksi | N12: =SUM(D12:M12) -> 0
B13: Discount | N13: =SUM(D13:M13) -> 0
B14: Tax/ pajak ( FULL PPN) | N14: =SUM(D14:M14) -> 0
B15: Penjualan Bersih | D15: =D8-D9-D10-D11-D12-D13-D14 -> 4454000 | E15: =E8-E9-E10-E11-E12-E13-E14 -> 3639000 | F15: =F8-F9-F10-F11-F12-F13-F14 -> 3173500 | G15: =G8-G9-G10-G11-G12-G13-G14 -> 3484000 | H15: =H8-H9-H10-H11-H12-H13-H14 -> 4920500 | I15: =I8-I9-I10-I11-I12-I13-I14 -> 4009000 | J15: =J8-J9-J10-J11-J12-J13-J14 -> 3711500 | K15: =K8-K9-K10-K11-K12-K13-K14 -> 0 | ... M15: =M8-M9-M10-M11-M12-M13-M14 -> 0 | N15: =SUM(D15:M15) -> 27391500
B16: Transferan grab food | N16: =SUM(D16:M16) -> 0
B17: Transferan gofood | N17: =SUM(D17:M17) -> 0
B18: Transferan shopee food | N18: =SUM(D18:M18) -> 0
B19: Q-Ris Gopay | N19: =SUM(D19:M19) -> 0
B20: Q-Ris Bank BSI | D20: 830500 | E20: 1042500 | F20: 787000 | G20: 607000 | H20: 1541500 | I20: 626500 | J20: 436000 | N20: =SUM(D20:M20) -> 5871000
B21: Q-Ris Ovo | N21: =SUM(D21:M21) -> 0
B22: Tax/Pajak ( SEBAGIAN PPN) | N22: =SUM(D22:M22) -> 0
B23: Selisih Kas | N23: =SUM(D23:M23) -> 0
N24: =SUM(D24:M24) -> 0
B25: Kas yang harus disetor | D25: =D15-D17-D18-D19-D20-D21-D22-D23-D16 -> 3623500 | E25: =E15-E17-E18-E19-E20-E21-E22-E23-E16 -> 2596500 | F25: =F15-F17-F18-F19-F20-F21-F22-F23-F16 -> 2386500 | G25: =G15-G17-G18-G19-G20-G21-G22-G23-G16 -> 2877000 | H25: =H15-H17-H18-H19-H20-H21-H22-H23-H16 -> 3379000 | I25: =I15-I17-I18-I19-I20-I21-I22-I23-I16 -> 3382500 | J25: =J15-J17-J18-J19-J20-J21-J22-J23-J16 -> 3275500 | K25: =K15-K17-K18-K19-K20-K21-K22-K23-K16 -> 0 | ... M25: =M15-M17-M18-M19-M20-M21-M22-M23-M16 -> 0 | N25: =SUM(D25:M25) -> 21520500
B26: No.Rizet PLU / TTL | N26: =SUM(D26:M26) -> 0
B27: Penjualan Mikas | N27: =SUM(D27:M27) -> 0
B28: Penjualan Lain - lain | N28: =SUM(D28:M28) -> 0
B29: Setor Bank | N29: =SUM(D29:M29) -> 0
B30: Setor Pihak Gedung | N30: =SUM(D30:M30) -> 0
B31: Jumlah Pembeli | D31: ='LAP. PENJUALAN REGULER'!D113 -> 81 | E31: ='LAP. PENJUALAN REGULER'!E113 -> 90 | F31: ='LAP. PENJUALAN REGULER'!F113 -> 87 | G31: ='LAP. PENJUALAN REGULER'!G113 -> 85 | H31: ='LAP. PENJUALAN REGULER'!H113 -> 96 | I31: ='LAP. PENJUALAN REGULER'!I113 -> 111 | J31: ='LAP. PENJUALAN REGULER'!J113 -> 96 | K31: ='LAP. PENJUALAN REGULER'!K113 -> 0 | ... M31: ='LAP. PENJUALAN REGULER'!M113 -> 0 | N31: =SUM(D31:M31) -> 646
M33: PARAF

Sheet LAP. PENJUALAN REGULER
A2: LAPORAN PENJUALAN REGULER
M3: Cabang : | O3: =LPKK!Q4 -> SC MARABAHAN
M4: Periode : | O4: =LPKK!Q5 -> 1-7 JULI 2026
A6: NO | B6: PRODUCT | C6: =B6 -> PRODUCT | D6: 1 | E6: 2 | F6: 3 | G6: 4 | H6: 5 | I6: 6 | J6: 7 | N6: TOTAL | P6: % | Q6: FC ITEM | R6: CON FC | S6: Harga
D7: Rabu | E7: Kamis | F7: Jum`at | G7: Sabtu | H7: Minggu | I7: Senin | J7: Sabtu | N7: UNIT | O7: ( Rp ) | S7: ( Unit )
A8: 1 | B8: Dada | C8: =B8 -> Dada | D8: 17 | E8: 13 | F8: 14 | G8: 13 | H8: 17 | I8: 23 | J8: 19 | N8: =SUM(D8:M8) -> 116 | O8: =N8*S8 -> 1740000 | P8: =(O8/O112)*100 -> 6.3523356 | Q8: ='FOOD COST PRODUCT'!G7 -> 0.54255249 | R8: =P8*Q8 -> 3.4464755 | S8: 15000 | U8: =D8*S8 -> 255000 | V8: =E8*S8 -> 195000 | W8: =F8*S8 -> 210000 | X8: =G8*S8 -> 195000 | Y8: =H8*S8 -> 255000 | Z8: =I8*S8 -> 345000 | AA8: =J8*S8 -> 285000 | AB8: =K8*S8 -> 0 | AC8: =L8*S8 -> 0 | AD8: =M8*S8 -> 0
A9: 2 | B9: Paha Atas | C9: =B9 -> Paha Atas | D9: 17 | E9: 12 | F9: 18 | G9: 10 | H9: 21 | I9: 8 | J9: 9 | N9: =SUM(D9:M9) -> 95 | O9: =N9*S9 -> 1425000 | P9: =(O9/O112)*100 -> 5.2023438 | Q9: ='FOOD COST PRODUCT'!G8 -> 0.55598999 | R9: =P9*Q9 -> 2.8924511 | S9: 15000 | U9: =D9*S9 -> 255000 | V9: =E9*S9 -> 180000 | W9: =F9*S9 -> 270000 | X9: =G9*S9 -> 150000 | Y9: =H9*S9 -> 315000 | Z9: =I9*S9 -> 120000 | AA9: =J9*S9 -> 135000 | AB9: =K9*S9 -> 0 | AC9: =L9*S9 -> 0 | AD9: =M9*S9 -> 0
A10: 3 | B10: Paha Bawah | C10: =B10 -> Paha Bawah | D10: 5 | E10: 4 | F10: 2 | H10: 2 | I10: 10 | J10: 5 | N10: =SUM(D10:M10) -> 28 | O10: =N10*S10 -> 378000 | P10: =(O10/O112)*100 -> 1.3799901 | Q10: ='FOOD COST PRODUCT'!G9 -> 0.48339166 | R10: =P10*Q10 -> 0.66707572 | S10: 13500 | U10: =D10*S10 -> 67500 | V10: =E10*S10 -> 54000 | W10: =F10*S10 -> 27000 | X10: =G10*S10 -> 0 | Y10: =H10*S10 -> 27000 | Z10: =I10*S10 -> 135000 | AA10: =J10*S10 -> 67500 | AB10: =K10*S10 -> 0 | AC10: =L10*S10 -> 0 | AD10: =M10*S10 -> 0
A11: 4 | B11: Sayap | C11: =B11 -> Sayap | D11: 11 | E11: 2 | F11: 5 | G11: 4 | H11: 3 | I11: 2 | N11: =SUM(D11:M11) -> 27 | O11: =N11*S11 -> 337500 | P11: =(O11/O112)*100 -> 1.2321341 | Q11: ='FOOD COST PRODUCT'!G10 -> 0.49038946 | R11: =P11*Q11 -> 0.60422555 | S11: 12500 | U11: =D11*S11 -> 137500 | V11: =E11*S11 -> 25000 | W11: =F11*S11 -> 62500 | X11: =G11*S11 -> 50000 | Y11: =H11*S11 -> 37500 | Z11: =I11*S11 -> 25000 | AA11: =J11*S11 -> 0 | AB11: =K11*S11 -> 0 | AC11: =L11*S11 -> 0 | AD11: =M11*S11 -> 0
A12: 5 | B12: Chicken Strips | C12: =B12 -> Chicken Strips | D12: 3 | E12: 6 | F12: 6 | G12: 7 | H12: 3 | I12: 1 | J12: 3 | N12: =SUM(D12:M12) -> 29 | O12: =N12*S12 -> 377000 | P12: =(O12/O112)*100 -> 1.3763394 | Q12: ='FOOD COST PRODUCT'!G11 -> 0.4245776 | R12: =P12*Q12 -> 0.58436287 | S12: 13000 | U12: =D12*S12 -> 39000 | V12: =E12*S12 -> 78000 | W12: =F12*S12 -> 78000 | X12: =G12*S12 -> 91000 | Y12: =H12*S12 -> 39000 | Z12: =I12*S12 -> 13000 | AA12: =J12*S12 -> 39000 | AB12: =K12*S12 -> 0 | AC12: =L12*S12 -> 0 | AD12: =M12*S12 -> 0
A13: 6 | B13: Chicken Steak | C13: =B13 -> Chicken Steak | D13: 1 | E13: 1 | H13: 3 | J13: 2 | N13: =SUM(D13:M13) -> 7 | O13: =N13*S13 -> 98000 | P13: =(O13/O112)*100 -> 0.35777522 | Q13: ='FOOD COST PRODUCT'!G12 -> 2.2252445 | R13: =P13*Q13 -> 0.79613733 | S13: 14000 | U13: =D13*S13 -> 14000 | V13: =E13*S13 -> 14000 | W13: =F13*S13 -> 0 | X13: =G13*S13 -> 0 | Y13: =H13*S13 -> 42000 | Z13: =I13*S13 -> 0 | AA13: =J13*S13 -> 28000 | AB13: =K13*S13 -> 0 | AC13: =L13*S13 -> 0 | AD13: =M13*S13 -> 0
A14: 7 | C14: Dada Lembut | N14: =SUM(D14:M14) -> 0 | O14: =N14*S14 -> 0 | P14: =(O14/O112)*100 -> 0 | Q14: ='FOOD COST PRODUCT'!G13 -> 0.54255249 | R14: =P14*Q14 -> 0 | S14: 15000 | U14: =D14*S14 -> 0 | V14: =E14*S14 -> 0 | W14: =F14*S14 -> 0 | X14: =G14*S14 -> 0 | Y14: =H14*S14 -> 0 | Z14: =I14*S14 -> 0 | AA14: =J14*S14 -> 0 | AB14: =K14*S14 -> 0 | AC14: =L14*S14 -> 0 | AD14: =M14*S14 -> 0
A15: 8 | B15: French Fries | C15: =B15 -> French Fries | D15: 8 | E15: 3 | G15: 1 | H15: 4 | I15: 2 | N15: =SUM(D15:M15) -> 18 | O15: =N15*S15 -> 216000 | P15: =(O15/O112)*100 -> 0.7885658 | Q15: ='FOOD COST PRODUCT'!G14 -> 0.36748104 | R15: =P15*Q15 -> 0.28978298 | S15: 12000 | U15: =D15*S15 -> 96000 | V15: =E15*S15 -> 36000 | W15: =F15*S15 -> 0 | X15: =G15*S15 -> 12000 | Y15: =H15*S15 -> 48000 | Z15: =I15*S15 -> 24000 | AA15: =J15*S15 -> 0 | AB15: =K15*S15 -> 0 | AC15: =L15*S15 -> 0 | AD15: =M15*S15 -> 0
A16: 9 | B16: Nasi | C16: =B16 -> Nasi | D16: 24 | E16: 26 | F16: 15 | G16: 13 | H16: 34 | I16: 22 | J16: 15 | N16: =SUM(D16:M16) -> 149 | O16: =N16*S16 -> 745000 | P16: =(O16/O112)*100 -> 2.7198218 | Q16: ='FOOD COST PRODUCT'!G15 -> 0.29554656 | R16: =P16*Q16 -> 0.80383399 | S16: 5000 | U16: =D16*S16 -> 120000 | V16: =E16*S16 -> 130000 | W16: =F16*S16 -> 75000 | X16: =G16*S16 -> 65000 | Y16: =H16*S16 -> 170000 | Z16: =I16*S16 -> 110000 | AA16: =J16*S16 -> 75000 | AB16: =K16*S16 -> 0 | AC16: =L16*S16 -> 0 | AD16: =M16*S16 -> 0
A17: 10 | B17: Perkedel | C17: =B17 -> Perkedel | D17: 14 | E17: 8 | F17: 9 | G17: 7 | H17: 5 | I17: 9 | J17: 6 | N17: =SUM(D17:M17) -> 58 | O17: =N17*S17 -> 348000 | P17: =(O17/O112)*100 -> 1.2704671 | Q17: ='FOOD COST PRODUCT'!G16 -> 0.75133429 | R17: =P17*Q17 -> 0.95454551 | S17: 6000 | U17: =D17*S17 -> 84000 | V17: =E17*S17 -> 48000 | W17: =F17*S17 -> 54000 | X17: =G17*S17 -> 42000 | Y17: =H17*S17 -> 30000 | Z17: =I17*S17 -> 54000 | AA17: =J17*S17 -> 36000 | AB17: =K17*S17 -> 0 | AC17: =L17*S17 -> 0 | AD17: =M17*S17 -> 0
A18: 11 | B18: Chicken Burger | C18: =B18 -> Chicken Burger | D18: 3 | E18: 2 | F18: 1 | G18: 1 | H18: 1 | I18: 1 | J18: 2 | N18: =SUM(D18:M18) -> 11 | O18: =N18*S18 -> 176000 | P18: =(O18/O112)*100 -> 0.64253509 | Q18: ='FOOD COST PRODUCT'!G17 -> 0.43699995 | R18: =P18*Q18 -> 0.2807878 | S18: 16000 | U18: =D18*S18 -> 48000 | V18: =E18*S18 -> 32000 | W18: =F18*S18 -> 16000 | X18: =G18*S18 -> 16000 | Y18: =H18*S18 -> 16000 | Z18: =I18*S18 -> 16000 | AA18: =J18*S18 -> 32000 | AB18: =K18*S18 -> 0 | AC18: =L18*S18 -> 0 | AD18: =M18*S18 -> 0
A19: 12 | B19: Cheese Burger | C19: =B19 -> Cheese Burger | D19: 4 | E19: 2 | F19: 1 | G19: 2 | H19: 3 | J19: 1 | N19: =SUM(D19:M19) -> 13 | O19: =N19*S19 -> 234000 | P19: =(O19/O112)*100 -> 0.85427961 | Q19: ='FOOD COST PRODUCT'!G18 -> 0.45322218 | R19: =P19*Q19 -> 0.38717847 | S19: 18000 | U19: =D19*S19 -> 72000 | V19: =E19*S19 -> 36000 | W19: =F19*S19 -> 18000 | X19: =G19*S19 -> 36000 | Y19: =H19*S19 -> 54000 | Z19: =I19*S19 -> 0 | AA19: =J19*S19 -> 18000 | AB19: =K19*S19 -> 0 | AC19: =L19*S19 -> 0 | AD19: =M19*S19 -> 0
A20: 13 | B20: Nasi Goreng | C20: =B20 -> Nasi Goreng | D20: 1 | F20: 3 | G20: 3 | N20: =SUM(D20:M20) -> 7 | O20: =N20*S20 -> 119000 | P20: =(O20/O112)*100 -> 0.43444134 | Q20: ='FOOD COST PRODUCT'!G19 -> 0.58392147 | R20: =P20*Q20 -> 0.25367963 | S20: 17000 | U20: =D20*S20 -> 17000 | V20: =E20*S20 -> 0 | W20: =F20*S20 -> 51000 | X20: =G20*S20 -> 51000 | Y20: =H20*S20 -> 0 | Z20: =I20*S20 -> 0 | AA20: =J20*S20 -> 0 | AB20: =K20*S20 -> 0 | AC20: =L20*S20 -> 0 | AD20: =M20*S20 -> 0
A21: 14 | B21: Telor Ceplok | C21: Nasi Goreng Spesial | E21: 1 | F21: 1 | G21: 4 | H21: 2 | J21: 1 | N21: =SUM(D21:M21) -> 9 | O21: =N21*S21 -> 180000 | P21: =(O21/O112)*100 -> 0.65713816 | Q21: ='FOOD COST PRODUCT'!G20 -> 0.5153519 | R21: =P21*Q21 -> 0.3386574 | S21: 20000 | U21: =D21*S21 -> 0 | V21: =E21*S21 -> 20000 | W21: =F21*S21 -> 20000 | X21: =G21*S21 -> 80000 | Y21: =H21*S21 -> 40000 | Z21: =I21*S21 -> 0 | AA21: =J21*S21 -> 20000 | AB21: =K21*S21 -> 0 | AC21: =L21*S21 -> 0 | AD21: =M21*S21 -> 0
A22: 15 | B22: Nasi Goreng Telor Ceplok | C22: Mie Goreng | D22: 1 | H22: 1 | N22: =SUM(D22:M22) -> 2 | O22: =N22*S22 -> 34000 | P22: =(O22/O112)*100 -> 0.1241261 | Q22: ='FOOD COST PRODUCT'!G21 -> 0.55171679 | R22: =P22*Q22 -> 0.068482452 | S22: 17000 | U22: =D22*S22 -> 17000 | V22: =E22*S22 -> 0 | W22: =F22*S22 -> 0 | X22: =G22*S22 -> 0 | Y22: =H22*S22 -> 17000 | Z22: =I22*S22 -> 0 | AA22: =J22*S22 -> 0 | AB22: =K22*S22 -> 0 | AC22: =L22*S22 -> 0 | AD22: =M22*S22 -> 0
A23: 16 | C23: Chicken 2 Pcs | D23: 1 | I23: 1 | N23: =SUM(D23:M23) -> 2 | O23: =N23*S23 -> 52000 | P23: =(O23/O112)*100 -> 0.18983991 | Q23: ='FOOD COST PRODUCT'!G22 -> 0.56400287 | R23: =P23*Q23 -> 0.10707026 | S23: 26000 | U23: =D23*S23 -> 26000 | V23: =E23*S23 -> 0 | W23: =F23*S23 -> 0 | X23: =G23*S23 -> 0 | Y23: =H23*S23 -> 0 | Z23: =I23*S23 -> 26000 | AA23: =J23*S23 -> 0 | AB23: =K23*S23 -> 0 | AC23: =L23*S23 -> 0 | AD23: =M23*S23 -> 0
A24: 17 | C24: Steak Blackpaper | H24: 1 | J24: 1 | N24: =SUM(D24:M24) -> 2 | O24: =N24*S24 -> 30000 | P24: =(O24/O112)*100 -> 0.10952303 | Q24: ='FOOD COST PRODUCT'!G23 -> 0 | R24: =P24*Q24 -> 0 | S24: 15000 | U24: =D24*S24 -> 0 | V24: =E24*S24 -> 0 | W24: =F24*S24 -> 0 | X24: =G24*S24 -> 0 | Y24: =H24*S24 -> 15000 | Z24: =I24*S24 -> 0 | AA24: =J24*S24 -> 15000 | AB24: =K24*S24 -> 0 | AC24: =L24*S24 -> 0 | AD24: =M24*S24 -> 0
A25: 18 | N25: =SUM(D25:M25) -> 0 | O25: =N25*S25 -> 0 | P25: =(O25/O112)*100 -> 0 | R25: =P25*Q25 -> 0 | U25: =D25*S25 -> 0 | V25: =E25*S25 -> 0 | W25: =F25*S25 -> 0 | X25: =G25*S25 -> 0 | Y25: =H25*S25 -> 0 | Z25: =I25*S25 -> 0 | AA25: =J25*S25 -> 0 | AB25: =K25*S25 -> 0 | AC25: =L25*S25 -> 0 | AD25: =M25*S25 -> 0
A26: 19 | B26: Paket Rocket 1 | C26: Paket Sonic 1 | D26: 40 | E26: 30 | F26: 25 | G26: 31 | H26: 45 | I26: 49 | J26: 28 | N26: =SUM(D26:M26) -> 248 | O26: =N26*S26 -> 3224000 | P26: =(O26/O112)*100 -> 11.770075 | Q26: ='FOOD COST PRODUCT'!G25 -> 0.84390064 | R26: =P26*Q26 -> 9.9327736 | S26: 13000 | U26: =D26*S26 -> 520000 | V26: =E26*S26 -> 390000 | W26: =F26*S26 -> 325000 | X26: =G26*S26 -> 403000 | Y26: =H26*S26 -> 585000 | Z26: =I26*S26 -> 637000 | AA26: =J26*S26 -> 364000 | AB26: =K26*S26 -> 0 | AC26: =L26*S26 -> 0 | AD26: =M26*S26 -> 0
A27: 20 | B27: Paket Rocket 2 | C27: Paket Sonic 2 | D27: 45 | E27: 24 | F27: 9 | G27: 23 | H27: 15 | I27: 41 | J27: 21 | N27: =SUM(D27:M27) -> 178 | O27: =N27*S27 -> 2670000 | P27: =(O27/O112)*100 -> 9.7475494 | Q27: ='FOOD COST PRODUCT'!G26 -> 2.3996175 | R27: =P27*Q27 -> 23.39039 | S27: 15000 | U27: =D27*S27 -> 675000 | V27: =E27*S27 -> 360000 | W27: =F27*S27 -> 135000 | X27: =G27*S27 -> 345000 | Y27: =H27*S27 -> 225000 | Z27: =I27*S27 -> 615000 | AA27: =J27*S27 -> 315000 | AB27: =K27*S27 -> 0 | AC27: =L27*S27 -> 0 | AD27: =M27*S27 -> 0
A28: 21 | B28: Paket Rocket 3 | C28: Paket Sonic 3 | D28: 4 | E28: 2 | F28: 6 | G28: 4 | H28: 3 | I28: 3 | J28: 2 | N28: =SUM(D28:M28) -> 24 | O28: =N28*S28 -> 624000 | P28: =(O28/O112)*100 -> 2.278079 | Q28: ='FOOD COST PRODUCT'!G27 -> 0.49919721 | R28: =P28*Q28 -> 1.1372107 | S28: 26000 | U28: =D28*S28 -> 104000 | V28: =E28*S28 -> 52000 | W28: =F28*S28 -> 156000 | X28: =G28*S28 -> 104000 | Y28: =H28*S28 -> 78000 | Z28: =I28*S28 -> 78000 | AA28: =J28*S28 -> 52000 | AB28: =K28*S28 -> 0 | AC28: =L28*S28 -> 0 | AD28: =M28*S28 -> 0
A29: 22 | B29: Paket Rocket 4 | C29: Paket Sonic 4 | D29: 5 | E29: 4 | F29: 5 | G29: 5 | H29: 1 | I29: 4 | J29: 6 | N29: =SUM(D29:M29) -> 30 | O29: =N29*S29 -> 780000 | P29: =(O29/O112)*100 -> 2.8475987 | Q29: ='FOOD COST PRODUCT'!G28 -> 0.50694961 | R29: =P29*Q29 -> 1.4435891 | S29: 26000 | U29: =D29*S29 -> 130000 | V29: =E29*S29 -> 104000 | W29: =F29*S29 -> 130000 | X29: =G29*S29 -> 130000 | Y29: =H29*S29 -> 26000 | Z29: =I29*S29 -> 104000 | AA29: =J29*S29 -> 156000 | AB29: =K29*S29 -> 0 | AC29: =L29*S29 -> 0 | AD29: =M29*S29 -> 0
A30: 23 | B30: Paket Rocket 5 | C30: Paket Sonic 5 | F30: 1 | N30: =SUM(D30:M30) -> 1 | O30: =N30*S30 -> 25000 | P30: =(O30/O112)*100 -> 0.091269189 | Q30: ='FOOD COST PRODUCT'!G29 -> 0.45015268 | R30: =P30*Q30 -> 0.04108507 | S30: 25000 | U30: =D30*S30 -> 0 | V30: =E30*S30 -> 0 | W30: =F30*S30 -> 25000 | X30: =G30*S30 -> 0 | Y30: =H30*S30 -> 0 | Z30: =I30*S30 -> 0 | AA30: =J30*S30 -> 0 | AB30: =K30*S30 -> 0 | AC30: =L30*S30 -> 0 | AD30: =M30*S30 -> 0
A31: 24 | B31: Paket Rocket 6 | C31: Paket Sonic 6 | D31: 2 | F31: 1 | G31: 2 | J31: 2 | N31: =SUM(D31:M31) -> 7 | O31: =N31*S31 -> 210000 | P31: =(O31/O112)*100 -> 0.76666119 | Q31: ='FOOD COST PRODUCT'!G30 -> 0.50788185 | R31: =P31*Q31 -> 0.3893733 | S31: 30000 | U31: =D31*S31 -> 60000 | V31: =E31*S31 -> 0 | W31: =F31*S31 -> 30000 | X31: =G31*S31 -> 60000 | Y31: =H31*S31 -> 0 | Z31: =I31*S31 -> 0 | AA31: =J31*S31 -> 60000 | AB31: =K31*S31 -> 0 | AC31: =L31*S31 -> 0 | AD31: =M31*S31 -> 0
A32: 25 | B32: Paket Rocket 7 | C32: Paket Sonic 7 | D32: 1 | F32: 2 | H32: 1 | I32: 1 | J32: 1 | N32: =SUM(D32:M32) -> 6 | O32: =N32*S32 -> 126000 | P32: =(O32/O112)*100 -> 0.45999671 | Q32: ='FOOD COST PRODUCT'!G31 -> 0.6753924 | R32: =P32*Q32 -> 0.31067829 | S32: 21000 | U32: =D32*S32 -> 21000 | V32: =E32*S32 -> 0 | W32: =F32*S32 -> 42000 | X32: =G32*S32 -> 0 | Y32: =H32*S32 -> 21000 | Z32: =I32*S32 -> 21000 | AA32: =J32*S32 -> 21000 | AB32: =K32*S32 -> 0 | AC32: =L32*S32 -> 0 | AD32: =M32*S32 -> 0
A33: 26 | C33: Paket Sonic 8 | G33: 1 | H33: 4 | I33: 1 | N33: =SUM(D33:M33) -> 6 | O33: =N33*S33 -> 150000 | P33: =(O33/O112)*100 -> 0.54761514 | Q33: ='FOOD COST PRODUCT'!G32 -> 1.4755092 | R33: =P33*Q33 -> 0.80801119 | S33: 25000 | U33: =D33*S33 -> 0 | V33: =E33*S33 -> 0 | W33: =F33*S33 -> 0 | X33: =G33*S33 -> 25000 | Y33: =H33*S33 -> 100000 | Z33: =I33*S33 -> 25000 | AA33: =J33*S33 -> 0 | AB33: =K33*S33 -> 0 | AC33: =L33*S33 -> 0 | AD33: =M33*S33 -> 0
A34: 27 | B34: Paket Rocket 8 | C34: Paket Sonic 9 | N34: =SUM(D34:M34) -> 0 | O34: =N34*S34 -> 0 | P34: =(O34/O112)*100 -> 0 | Q34: ='FOOD COST PRODUCT'!G33 -> 0.63065712 | R34: =P34*Q34 -> 0 | U34: =D34*S34 -> 0 | V34: =E34*S34 -> 0 | W34: =F34*S34 -> 0 | X34: =G34*S34 -> 0 | Y34: =H34*S34 -> 0 | Z34: =I34*S34 -> 0 | AA34: =J34*S34 -> 0 | AB34: =K34*S34 -> 0 | AC34: =L34*S34 -> 0 | AD34: =M34*S34 -> 0
A35: 28 | O35: =N35*S35 -> 0 | P35: =(O35/O112)*100 -> 0 | R35: =P35*Q35 -> 0 | U35: =D35*S35 -> 0 | V35: =E35*S35 -> 0 | W35: =F35*S35 -> 0 | X35: =G35*S35 -> 0 | Y35: =H35*S35 -> 0 | Z35: =I35*S35 -> 0 | AA35: =J35*S35 -> 0 | AB35: =K35*S35 -> 0 | AC35: =L35*S35 -> 0 | AD35: =M35*S35 -> 0
A36: 29 | B36: Paket Rocket 9 | C36: Paket Gepso 1 | D36: 4 | F36: 1 | G36: 1 | H36: 2 | J36: 1 | N36: =SUM(D36:M36) -> 9 | O36: =N36*S36 -> 216000 | P36: =(O36/O112)*100 -> 0.7885658 | Q36: ='FOOD COST PRODUCT'!G35 -> 0.75815065 | R36: =P36*Q36 -> 0.59785167 | S36: 24000 | U36: =D36*S36 -> 96000 | V36: =E36*S36 -> 0 | W36: =F36*S36 -> 24000 | X36: =G36*S36 -> 24000 | Y36: =H36*S36 -> 48000 | Z36: =I36*S36 -> 0 | AA36: =J36*S36 -> 24000 | AB36: =K36*S36 -> 0 | AC36: =L36*S36 -> 0 | AD36: =M36*S36 -> 0
A37: 30 | B37: Paket Rocket 10 | C37: Paket Gepso 2 | D37: 2 | G37: 1 | H37: 2 | I37: 1 | N37: =SUM(D37:M37) -> 6 | O37: =N37*S37 -> 150000 | P37: =(O37/O112)*100 -> 0.54761514 | Q37: ='FOOD COST PRODUCT'!G36 -> 0.74366139 | R37: =P37*Q37 -> 0.40724023 | S37: 25000 | U37: =D37*S37 -> 50000 | V37: =E37*S37 -> 0 | W37: =F37*S37 -> 0 | X37: =G37*S37 -> 25000 | Y37: =H37*S37 -> 50000 | Z37: =I37*S37 -> 25000 | AA37: =J37*S37 -> 0 | AB37: =K37*S37 -> 0 | AC37: =L37*S37 -> 0 | AD37: =M37*S37 -> 0
A38: 31 | C38: Paket Gepso 3 | D38: 1 | E38: 2 | F38: 1 | G38: 3 | H38: 7 | I38: 1 | J38: 5 | N38: =SUM(D38:M38) -> 20 | O38: =N38*S38 -> 540000 | P38: =(O38/O112)*100 -> 1.9714145 | Q38: ='FOOD COST PRODUCT'!G37 -> 0.74829758 | R38: =P38*Q38 -> 1.4752047 | S38: 27000 | U38: =D38*S38 -> 27000 | V38: =E38*S38 -> 54000 | W38: =F38*S38 -> 27000 | X38: =G38*S38 -> 81000 | Y38: =H38*S38 -> 189000 | Z38: =I38*S38 -> 27000 | AA38: =J38*S38 -> 135000 | AB38: =K38*S38 -> 0 | AC38: =L38*S38 -> 0 | AD38: =M38*S38 -> 0
A39: 32 | C39: Paket Gepso 4 | F39: 1 | G39: 2 | H39: 2 | I39: 2 | J39: 1 | N39: =SUM(D39:M39) -> 8 | O39: =N39*S39 -> 216000 | P39: =(O39/O112)*100 -> 0.7885658 | Q39: ='FOOD COST PRODUCT'!G38 -> 0.75576286 | R39: =P39*Q39 -> 0.59596874 | S39: 27000 | U39: =D39*S39 -> 0 | V39: =E39*S39 -> 0 | W39: =F39*S39 -> 27000 | X39: =G39*S39 -> 54000 | Y39: =H39*S39 -> 54000 | Z39: =I39*S39 -> 54000 | AA39: =J39*S39 -> 27000 | AB39: =K39*S39 -> 0 | AC39: =L39*S39 -> 0 | AD39: =M39*S39 -> 0
A40: 33 | B40: Paket Roma 1 | O40: =N40*S40 -> 0 | P40: =(O40/O112)*100 -> 0 | R40: =P40*Q40 -> 0 | U40: =D40*S40 -> 0 | V40: =E40*S40 -> 0 | W40: =F40*S40 -> 0 | X40: =G40*S40 -> 0 | Y40: =H40*S40 -> 0 | Z40: =I40*S40 -> 0 | AA40: =J40*S40 -> 0 | AB40: =K40*S40 -> 0 | AC40: =L40*S40 -> 0 | AD40: =M40*S40 -> 0
A41: 34 | B41: Paket Roma 2 | C41: Paket Prenic 1 | E41: 1 | F41: 4 | H41: 2 | N41: =SUM(D41:M41) -> 7 | O41: =N41*S41 -> 175000 | P41: =(O41/O112)*100 -> 0.63888433 | Q41: ='FOOD COST PRODUCT'!G40 -> 0.51554206 | R41: =P41*Q41 -> 0.32937174 | S41: 25000 | U41: =D41*S41 -> 0 | V41: =E41*S41 -> 25000 | W41: =F41*S41 -> 100000 | X41: =G41*S41 -> 0 | Y41: =H41*S41 -> 50000 | Z41: =I41*S41 -> 0 | AA41: =J41*S41 -> 0 | AB41: =K41*S41 -> 0 | AC41: =L41*S41 -> 0 | AD41: =M41*S41 -> 0
A42: 35 | B42: Paket Roma 3 | C42: Paket Prenic 2 | H42: 1 | N42: =SUM(D42:M42) -> 1 | O42: =N42*S42 -> 26000 | P42: =(O42/O112)*100 -> 0.094919957 | Q42: ='FOOD COST PRODUCT'!G41 -> 0.47793573 | R42: =P42*Q42 -> 0.045365639 | S42: 26000 | U42: =D42*S42 -> 0 | V42: =E42*S42 -> 0 | W42: =F42*S42 -> 0 | X42: =G42*S42 -> 0 | Y42: =H42*S42 -> 26000 | Z42: =I42*S42 -> 0 | AA42: =J42*S42 -> 0 | AB42: =K42*S42 -> 0 | AC42: =L42*S42 -> 0 | AD42: =M42*S42 -> 0
...

Sheet LAP. PENJUALAN GRABFOOD
A2: LAPORAN PENJUALAN GRABFOOD
M3: Cabang : | O3: =LPKK!Q4 -> SC MARABAHAN
M4: Periode : | O4: =LPKK!Q5 -> 1-7 JULI 2026
A6: NO | B6: PRODUCT | C6: =B6 -> PRODUCT | D6: ='LAP. PENJUALAN REGULER'!D6 -> 1 | E6: ='LAP. PENJUALAN REGULER'!E6 -> 2 | F6: ='LAP. PENJUALAN REGULER'!F6 -> 3 | G6: ='LAP. PENJUALAN REGULER'!G6 -> 4 | H6: ='LAP. PENJUALAN REGULER'!H6 -> 5 | I6: ='LAP. PENJUALAN REGULER'!I6 -> 6 | J6: ='LAP. PENJUALAN REGULER'!J6 -> 7 | K6: ='LAP. PENJUALAN REGULER'!K6 -> 0 | ... M6: ='LAP. PENJUALAN REGULER'!M6 -> 0 | N6: TOTAL | P6: % | Q6: FC ITEM | R6: CON FC | S6: Harga
D7: ='LAP. PENJUALAN REGULER'!D7 -> Rabu | E7: ='LAP. PENJUALAN REGULER'!E7 -> Kamis | F7: ='LAP. PENJUALAN REGULER'!F7 -> Jum`at | G7: ='LAP. PENJUALAN REGULER'!G7 -> Sabtu | H7: ='LAP. PENJUALAN REGULER'!H7 -> Minggu | I7: ='LAP. PENJUALAN REGULER'!I7 -> Senin | J7: ='LAP. PENJUALAN REGULER'!J7 -> Sabtu | K7: ='LAP. PENJUALAN REGULER'!K7 -> 0 | ... M7: ='LAP. PENJUALAN REGULER'!M7 -> 0 | N7: UNIT | O7: ( Rp ) | S7: ( Unit )
A8: 1 | B8: Dada | C8: =B8 -> Dada | N8: =SUM(D8:M8) -> 0 | O8: =N8*S8 -> 0 | P8: =(O8/O112)*100 -> #DIV/0! | R8: =P8*Q8 -> #DIV/0! | S8: 19575 | U8: =D8*S8 -> 0 | V8: =E8*S8 -> 0 | W8: =F8*S8 -> 0 | X8: =G8*S8 -> 0 | Y8: =H8*S8 -> 0 | Z8: =I8*S8 -> 0 | AA8: =J8*S8 -> 0 | AB8: =K8*S8 -> 0 | AC8: =L8*S8 -> 0 | AD8: =M8*S8 -> 0
A9: 2 | B9: Paha Atas | C9: =B9 -> Paha Atas | N9: =SUM(D9:M9) -> 0 | O9: =N9*S9 -> 0 | P9: =(O9/O112)*100 -> #DIV/0! | R9: =P9*Q9 -> #DIV/0! | S9: 19575 | U9: =D9*S9 -> 0 | V9: =E9*S9 -> 0 | W9: =F9*S9 -> 0 | X9: =G9*S9 -> 0 | Y9: =H9*S9 -> 0 | Z9: =I9*S9 -> 0 | AA9: =J9*S9 -> 0 | AB9: =K9*S9 -> 0 | AC9: =L9*S9 -> 0 | AD9: =M9*S9 -> 0
A10: 3 | B10: Paha Bawah | C10: =B10 -> Paha Bawah | N10: =SUM(D10:M10) -> 0 | O10: =N10*S10 -> 0 | P10: =(O10/O112)*100 -> #DIV/0! | R10: =P10*Q10 -> #DIV/0! | S10: 17550 | U10: =D10*S10 -> 0 | V10: =E10*S10 -> 0 | W10: =F10*S10 -> 0 | X10: =G10*S10 -> 0 | Y10: =H10*S10 -> 0 | Z10: =I10*S10 -> 0 | AA10: =J10*S10 -> 0 | AB10: =K10*S10 -> 0 | AC10: =L10*S10 -> 0 | AD10: =M10*S10 -> 0
A11: 4 | B11: Sayap | C11: =B11 -> Sayap | N11: =SUM(D11:M11) -> 0 | O11: =N11*S11 -> 0 | P11: =(O11/O112)*100 -> #DIV/0! | R11: =P11*Q11 -> #DIV/0! | S11: 16200 | U11: =D11*S11 -> 0 | V11: =E11*S11 -> 0 | W11: =F11*S11 -> 0 | X11: =G11*S11 -> 0 | Y11: =H11*S11 -> 0 | Z11: =I11*S11 -> 0 | AA11: =J11*S11 -> 0 | AB11: =K11*S11 -> 0 | AC11: =L11*S11 -> 0 | AD11: =M11*S11 -> 0
A12: 5 | B12: Chicken Strips | C12: =B12 -> Chicken Strips | N12: =SUM(D12:M12) -> 0 | O12: =N12*S12 -> 0 | P12: =(O12/O112)*100 -> #DIV/0! | R12: =P12*Q12 -> #DIV/0! | S12: 16200 | U12: =D12*S12 -> 0 | V12: =E12*S12 -> 0 | W12: =F12*S12 -> 0 | X12: =G12*S12 -> 0 | Y12: =H12*S12 -> 0 | Z12: =I12*S12 -> 0 | AA12: =J12*S12 -> 0 | AB12: =K12*S12 -> 0 | AC12: =L12*S12 -> 0 | AD12: =M12*S12 -> 0
A13: 6 | B13: Chicken Steak | C13: =B13 -> Chicken Steak | N13: =SUM(D13:M13) -> 0 | O13: =N13*S13 -> 0 | P13: =(O13/O112)*100 -> #DIV/0! | R13: =P13*Q13 -> #DIV/0! | S13: 17550 | U13: =D13*S13 -> 0 | V13: =E13*S13 -> 0 | W13: =F13*S13 -> 0 | X13: =G13*S13 -> 0 | Y13: =H13*S13 -> 0 | Z13: =I13*S13 -> 0 | AA13: =J13*S13 -> 0 | AB13: =K13*S13 -> 0 | AC13: =L13*S13 -> 0 | AD13: =M13*S13 -> 0
